Workbook
Name NEW_BLOCK_TEMPLATE: 'Pull Sheet'!$S$5:$W$36

Sheet Pull Sheet
A1: LED PULL SHEET
A2: SHOW: | D2: DATE:
A3: ENGINEER: | D3: REV:
A5: POSITION 1 | G5: POSITION 2 | M5: POSITION 3 | S5: NEW POSITION | U5: < copy to add a position >
A6: Cable Type | B6: Length | C6: Qty | D6: Label | E6: Notes | G6: Cable Type | H6: Length | I6: Qty | J6: Label | K6: Notes | M6: Cable Type | N6: Length | O6: Qty | P6: Label | Q6: Notes | S6: Cable Type | T6: Length | U6: Qty | V6: Label | W6: Notes

Sheet Spares
A1: SPARES
A2: Auto-built from the Pull Sheet. Only shows what you actually have. Rounded up.
A3: SPARE %: | B3: 0.1 | C3: < change this, everything updates
A5: Cable Type | B5: Length | C5: Needed | D5: Spares
A6: =IF($F6="","",LEFT($F6,FIND("|",$F6)-1)) | B6: =IF($F6="","",MID($F6,FIND("|",$F6)+1,50)) | C6: =IF($F6="","",SUMIF(calc!$A:$A,$F6,calc!$C:$C)) | D6: =IF($F6="","",ROUNDUP($C6*$B$3,0)) | F6: {=IFERROR(INDEX(calc!$A:$A,MATCH(1,calc!$E:$E,0)),"")}
A7: =IF($F7="","",LEFT($F7,FIND("|",$F7)-1)) | B7: =IF($F7="","",MID($F7,FIND("|",$F7)+1,50)) | C7: =IF($F7="","",SUMIF(calc!$A:$A,$F7,calc!$C:$C)) | D7: =IF($F7="","",ROUNDUP($C7*$B$3,0)) | F7: {=IFERROR(INDEX(calc!$A:$A,MATCH(2,calc!$E:$E,0)),"")}
A8: =IF($F8="","",LEFT($F8,FIND("|",$F8)-1)) | B8: =IF($F8="","",MID($F8,FIND("|",$F8)+1,50)) | C8: =IF($F8="","",SUMIF(calc!$A:$A,$F8,calc!$C:$C)) | D8: =IF($F8="","",ROUNDUP($C8*$B$3,0)) | F8: {=IFERROR(INDEX(calc!$A:$A,MATCH(3,calc!$E:$E,0)),"")}
A9: =IF($F9="","",LEFT($F9,FIND("|",$F9)-1)) | B9: =IF($F9="","",MID($F9,FIND("|",$F9)+1,50)) | C9: =IF($F9="","",SUMIF(calc!$A:$A,$F9,calc!$C:$C)) | D9: =IF($F9="","",ROUNDUP($C9*$B$3,0)) | F9: {=IFERROR(INDEX(calc!$A:$A,MATCH(4,calc!$E:$E,0)),"")}
A10: =IF($F10="","",LEFT($F10,FIND("|",$F10)-1)) | B10: =IF($F10="","",MID($F10,FIND("|",$F10)+1,50)) | C10: =IF($F10="","",SUMIF(calc!$A:$A,$F10,calc!$C:$C)) | D10: =IF($F10="","",ROUNDUP($C10*$B$3,0)) | F10: {=IFERROR(INDEX(calc!$A:$A,MATCH(5,calc!$E:$E,0)),"")}
A11: =IF($F11="","",LEFT($F11,FIND("|",$F11)-1)) | B11: =IF($F11="","",MID($F11,FIND("|",$F11)+1,50)) | C11: =IF($F11="","",SUMIF(calc!$A:$A,$F11,calc!$C:$C)) | D11: =IF($F11="","",ROUNDUP($C11*$B$3,0)) | F11: {=IFERROR(INDEX(calc!$A:$A,MATCH(6,calc!$E:$E,0)),"")}
A12: =IF($F12="","",LEFT($F12,FIND("|",$F12)-1)) | B12: =IF($F12="","",MID($F12,FIND("|",$F12)+1,50)) | C12: =IF($F12="","",SUMIF(calc!$A:$A,$F12,calc!$C:$C)) | D12: =IF($F12="","",ROUNDUP($C12*$B$3,0)) | F12: {=IFERROR(INDEX(calc!$A:$A,MATCH(7,calc!$E:$E,0)),"")}
A13: =IF($F13="","",LEFT($F13,FIND("|",$F13)-1)) | B13: =IF($F13="","",MID($F13,FIND("|",$F13)+1,50)) | C13: =IF($F13="","",SUMIF(calc!$A:$A,$F13,calc!$C:$C)) | D13: =IF($F13="","",ROUNDUP($C13*$B$3,0)) | F13: {=IFERROR(INDEX(calc!$A:$A,MATCH(8,calc!$E:$E,0)),"")}
A14: =IF($F14="","",LEFT($F14,FIND("|",$F14)-1)) | B14: =IF($F14="","",MID($F14,FIND("|",$F14)+1,50)) | C14: =IF($F14="","",SUMIF(calc!$A:$A,$F14,calc!$C:$C)) | D14: =IF($F14="","",ROUNDUP($C14*$B$3,0)) | F14: {=IFERROR(INDEX(calc!$A:$A,MATCH(9,calc!$E:$E,0)),"")}
A15: =IF($F15="","",LEFT($F15,FIND("|",$F15)-1)) | B15: =IF($F15="","",MID($F15,FIND("|",$F15)+1,50)) | C15: =IF($F15="","",SUMIF(calc!$A:$A,$F15,calc!$C:$C)) | D15: =IF($F15="","",ROUNDUP($C15*$B$3,0)) | F15: {=IFERROR(INDEX(calc!$A:$A,MATCH(10,calc!$E:$E,0)),"")}
A16: =IF($F16="","",LEFT($F16,FIND("|",$F16)-1)) | B16: =IF($F16="","",MID($F16,FIND("|",$F16)+1,50)) | C16: =IF($F16="","",SUMIF(calc!$A:$A,$F16,calc!$C:$C)) | D16: =IF($F16="","",ROUNDUP($C16*$B$3,0)) | F16: {=IFERROR(INDEX(calc!$A:$A,MATCH(11,calc!$E:$E,0)),"")}
A17: =IF($F17="","",LEFT($F17,FIND("|",$F17)-1)) | B17: =IF($F17="","",MID($F17,FIND("|",$F17)+1,50)) | C17: =IF($F17="","",SUMIF(calc!$A:$A,$F17,calc!$C:$C)) | D17: =IF($F17="","",ROUNDUP($C17*$B$3,0)) | F17: {=IFERROR(INDEX(calc!$A:$A,MATCH(12,calc!$E:$E,0)),"")}
A18: =IF($F18="","",LEFT($F18,FIND("|",$F18)-1)) | B18: =IF($F18="","",MID($F18,FIND("|",$F18)+1,50)) | C18: =IF($F18="","",SUMIF(calc!$A:$A,$F18,calc!$C:$C)) | D18: =IF($F18="","",ROUNDUP($C18*$B$3,0)) | F18: {=IFERROR(INDEX(calc!$A:$A,MATCH(13,calc!$E:$E,0)),"")}
A19: =IF($F19="","",LEFT($F19,FIND("|",$F19)-1)) | B19: =IF($F19="","",MID($F19,FIND("|",$F19)+1,50)) | C19: =IF($F19="","",SUMIF(calc!$A:$A,$F19,calc!$C:$C)) | D19: =IF($F19="","",ROUNDUP($C19*$B$3,0)) | F19: {=IFERROR(INDEX(calc!$A:$A,MATCH(14,calc!$E:$E,0)),"")}
A20: =IF($F20="","",LEFT($F20,FIND("|",$F20)-1)) | B20: =IF($F20="","",MID($F20,FIND("|",$F20)+1,50)) | C20: =IF($F20="","",SUMIF(calc!$A:$A,$F20,calc!$C:$C)) | D20: =IF($F20="","",ROUNDUP($C20*$B$3,0)) | F20: {=IFERROR(INDEX(calc!$A:$A,MATCH(15,calc!$E:$E,0)),"")}
A21: =IF($F21="","",LEFT($F21,FIND("|",$F21)-1)) | B21: =IF($F21="","",MID($F21,FIND("|",$F21)+1,50)) | C21: =IF($F21="","",SUMIF(calc!$A:$A,$F21,calc!$C:$C)) | D21: =IF($F21="","",ROUNDUP($C21*$B$3,0)) | F21: {=IFERROR(INDEX(calc!$A:$A,MATCH(16,calc!$E:$E,0)),"")}
A22: =IF($F22="","",LEFT($F22,FIND("|",$F22)-1)) | B22: =IF($F22="","",MID($F22,FIND("|",$F22)+1,50)) | C22: =IF($F22="","",SUMIF(calc!$A:$A,$F22,calc!$C:$C)) | D22: =IF($F22="","",ROUNDUP($C22*$B$3,0)) | F22: {=IFERROR(INDEX(calc!$A:$A,MATCH(17,calc!$E:$E,0)),"")}
A23: =IF($F23="","",LEFT($F23,FIND("|",$F23)-1)) | B23: =IF($F23="","",MID($F23,FIND("|",$F23)+1,50)) | C23: =IF($F23="","",SUMIF(calc!$A:$A,$F23,calc!$C:$C)) | D23: =IF($F23="","",ROUNDUP($C23*$B$3,0)) | F23: {=IFERROR(INDEX(calc!$A:$A,MATCH(18,calc!$E:$E,0)),"")}
A24: =IF($F24="","",LEFT($F24,FIND("|",$F24)-1)) | B24: =IF($F24="","",MID($F24,FIND("|",$F24)+1,50)) | C24: =IF($F24="","",SUMIF(calc!$A:$A,$F24,calc!$C:$C)) | D24: =IF($F24="","",ROUNDUP($C24*$B$3,0)) | F24: {=IFERROR(INDEX(calc!$A:$A,MATCH(19,calc!$E:$E,0)),"")}
A25: =IF($F25="","",LEFT($F25,FIND("|",$F25)-1)) | B25: =IF($F25="","",MID($F25,FIND("|",$F25)+1,50)) | C25: =IF($F25="","",SUMIF(calc!$A:$A,$F25,calc!$C:$C)) | D25: =IF($F25="","",ROUNDUP($C25*$B$3,0)) | F25: {=IFERROR(INDEX(calc!$A:$A,MATCH(20,calc!$E:$E,0)),"")}
A26: =IF($F26="","",LEFT($F26,FIND("|",$F26)-1)) | B26: =IF($F26="","",MID($F26,FIND("|",$F26)+1,50)) | C26: =IF($F26="","",SUMIF(calc!$A:$A,$F26,calc!$C:$C)) | D26: =IF($F26="","",ROUNDUP($C26*$B$3,0)) | F26: {=IFERROR(INDEX(calc!$A:$A,MATCH(21,calc!$E:$E,0)),"")}
A27: =IF($F27="","",LEFT($F27,FIND("|",$F27)-1)) | B27: =IF($F27="","",MID($F27,FIND("|",$F27)+1,50)) | C27: =IF($F27="","",SUMIF(calc!$A:$A,$F27,calc!$C:$C)) | D27: =IF($F27="","",ROUNDUP($C27*$B$3,0)) | F27: {=IFERROR(INDEX(calc!$A:$A,MATCH(22,calc!$E:$E,0)),"")}
A28: =IF($F28="","",LEFT($F28,FIND("|",$F28)-1)) | B28: =IF($F28="","",MID($F28,FIND("|",$F28)+1,50)) | C28: =IF($F28="","",SUMIF(calc!$A:$A,$F28,calc!$C:$C)) | D28: =IF($F28="","",ROUNDUP($C28*$B$3,0)) | F28: {=IFERROR(INDEX(calc!$A:$A,MATCH(23,calc!$E:$E,0)),"")}
A29: =IF($F29="","",LEFT($F29,FIND("|",$F29)-1)) | B29: =IF($F29="","",MID($F29,FIND("|",$F29)+1,50)) | C29: =IF($F29="","",SUMIF(calc!$A:$A,$F29,calc!$C:$C)) | D29: =IF($F29="","",ROUNDUP($C29*$B$3,0)) | F29: {=IFERROR(INDEX(calc!$A:$A,MATCH(24,calc!$E:$E,0)),"")}
A30: =IF($F30="","",LEFT($F30,FIND("|",$F30)-1)) | B30: =IF($F30="","",MID($F30,FIND("|",$F30)+1,50)) | C30: =IF($F30="","",SUMIF(calc!$A:$A,$F30,calc!$C:$C)) | D30: =IF($F30="","",ROUNDUP($C30*$B$3,0)) | F30: {=IFERROR(INDEX(calc!$A:$A,MATCH(25,calc!$E:$E,0)),"")}
A31: =IF($F31="","",LEFT($F31,FIND("|",$F31)-1)) | B31: =IF($F31="","",MID($F31,FIND("|",$F31)+1,50)) | C31: =IF($F31="","",SUMIF(calc!$A:$A,$F31,calc!$C:$C)) | D31: =IF($F31="","",ROUNDUP($C31*$B$3,0)) | F31: {=IFERROR(INDEX(calc!$A:$A,MATCH(26,calc!$E:$E,0)),"")}
A32: =IF($F32="","",LEFT($F32,FIND("|",$F32)-1)) | B32: =IF($F32="","",MID($F32,FIND("|",$F32)+1,50)) | C32: =IF($F32="","",SUMIF(calc!$A:$A,$F32,calc!$C:$C)) | D32: =IF($F32="","",ROUNDUP($C32*$B$3,0)) | F32: {=IFERROR(INDEX(calc!$A:$A,MATCH(27,calc!$E:$E,0)),"")}
A33: =IF($F33="","",LEFT($F33,FIND("|",$F33)-1)) | B33: =IF($F33="","",MID($F33,FIND("|",$F33)+1,50)) | C33: =IF($F33="","",SUMIF(calc!$A:$A,$F33,calc!$C:$C)) | D33: =IF($F33="","",ROUNDUP($C33*$B$3,0)) | F33: {=IFERROR(INDEX(calc!$A:$A,MATCH(28,calc!$E:$E,0)),"")}
A34: =IF($F34="","",LEFT($F34,FIND("|",$F34)-1)) | B34: =IF($F34="","",MID($F34,FIND("|",$F34)+1,50)) | C34: =IF($F34="","",SUMIF(calc!$A:$A,$F34,calc!$C:$C)) | D34: =IF($F34="","",ROUNDUP($C34*$B$3,0)) | F34: {=IFERROR(INDEX(calc!$A:$A,MATCH(29,calc!$E:$E,0)),"")}
A35: =IF($F35="","",LEFT($F35,FIND("|",$F35)-1)) | B35: =IF($F35="","",MID($F35,FIND("|",$F35)+1,50)) | C35: =IF($F35="","",SUMIF(calc!$A:$A,$F35,calc!$C:$C)) | D35: =IF($F35="","",ROUNDUP($C35*$B$3,0)) | F35: {=IFERROR(INDEX(calc!$A:$A,MATCH(30,calc!$E:$E,0)),"")}
A36: =IF($F36="","",LEFT($F36,FIND("|",$F36)-1)) | B36: =IF($F36="","",MID($F36,FIND("|",$F36)+1,50)) | C36: =IF($F36="","",SUMIF(calc!$A:$A,$F36,calc!$C:$C)) | D36: =IF($F36="","",ROUNDUP($C36*$B$3,0)) | F36: {=IFERROR(INDEX(calc!$A:$A,MATCH(31,calc!$E:$E,0)),"")}
A37: =IF($F37="","",LEFT($F37,FIND("|",$F37)-1)) | B37: =IF($F37="","",MID($F37,FIND("|",$F37)+1,50)) | C37: =IF($F37="","",SUMIF(calc!$A:$A,$F37,calc!$C:$C)) | D37: =IF($F37="","",ROUNDUP($C37*$B$3,0)) | F37: {=IFERROR(INDEX(calc!$A:$A,MATCH(32,calc!$E:$E,0)),"")}
A38: =IF($F38="","",LEFT($F38,FIND("|",$F38)-1)) | B38: =IF($F38="","",MID($F38,FIND("|",$F38)+1,50)) | C38: =IF($F38="","",SUMIF(calc!$A:$A,$F38,calc!$C:$C)) | D38: =IF($F38="","",ROUNDUP($C38*$B$3,0)) | F38: {=IFERROR(INDEX(calc!$A:$A,MATCH(33,calc!$E:$E,0)),"")}
A39: =IF($F39="","",LEFT($F39,FIND("|",$F39)-1)) | B39: =IF($F39="","",MID($F39,FIND("|",$F39)+1,50)) | C39: =IF($F39="","",SUMIF(calc!$A:$A,$F39,calc!$C:$C)) | D39: =IF($F39="","",ROUNDUP($C39*$B$3,0)) | F39: {=IFERROR(INDEX(calc!$A:$A,MATCH(34,calc!$E:$E,0)),"")}
A40: =IF($F40="","",LEFT($F40,FIND("|",$F40)-1)) | B40: =IF($F40="","",MID($F40,FIND("|",$F40)+1,50)) | C40: =IF($F40="","",SUMIF(calc!$A:$A,$F40,calc!$C:$C)) | D40: =IF($F40="","",ROUNDUP($C40*$B$3,0)) | F40: {=IFERROR(INDEX(calc!$A:$A,MATCH(35,calc!$E:$E,0)),"")}
A41: =IF($F41="","",LEFT($F41,FIND("|",$F41)-1)) | B41: =IF($F41="","",MID($F41,FIND("|",$F41)+1,50)) | C41: =IF($F41="","",SUMIF(calc!$A:$A,$F41,calc!$C:$C)) | D41: =IF($F41="","",ROUNDUP($C41*$B$3,0)) | F41: {=IFERROR(INDEX(calc!$A:$A,MATCH(36,calc!$E:$E,0)),"")}
...

Sheet TOTALS
A1: TOTALS - SHOP PULL
A2: Builds itself from every position on the Pull Sheet. Only lists cables you actually have. Spares = qty x spare %.
A4: Cable Type | B4: Length | C4: Qty | D4: Spares | E4: TOTAL
A5: =IF($H5="","",LEFT($H5,FIND("|",$H5)-1)) | B5: =IF($H5="","",MID($H5,FIND("|",$H5)+1,50)) | C5: =IF($H5="","",SUMIF(calc!$A:$A,$H5,calc!$C:$C)) | D5: =IF($H5="","",ROUNDUP($C5*Spares!$B$3,0)) | E5: =IF($H5="","",$C5+$D5) | H5: {=IFERROR(INDEX(calc!$A:$A,MATCH(1,calc!$E:$E,0)),"")}
A6: =IF($H6="","",LEFT($H6,FIND("|",$H6)-1)) | B6: =IF($H6="","",MID($H6,FIND("|",$H6)+1,50)) | C6: =IF($H6="","",SUMIF(calc!$A:$A,$H6,calc!$C:$C)) | D6: =IF($H6="","",ROUNDUP($C6*Spares!$B$3,0)) | E6: =IF($H6="","",$C6+$D6) | H6: {=IFERROR(INDEX(calc!$A:$A,MATCH(2,calc!$E:$E,0)),"")}
A7: =IF($H7="","",LEFT($H7,FIND("|",$H7)-1)) | B7: =IF($H7="","",MID($H7,FIND("|",$H7)+1,50)) | C7: =IF($H7="","",SUMIF(calc!$A:$A,$H7,calc!$C:$C)) | D7: =IF($H7="","",ROUNDUP($C7*Spares!$B$3,0)) | E7: =IF($H7="","",$C7+$D7) | H7: {=IFERROR(INDEX(calc!$A:$A,MATCH(3,calc!$E:$E,0)),"")}
A8: =IF($H8="","",LEFT($H8,FIND("|",$H8)-1)) | B8: =IF($H8="","",MID($H8,FIND("|",$H8)+1,50)) | C8: =IF($H8="","",SUMIF(calc!$A:$A,$H8,calc!$C:$C)) | D8: =IF($H8="","",ROUNDUP($C8*Spares!$B$3,0)) | E8: =IF($H8="","",$C8+$D8) | H8: {=IFERROR(INDEX(calc!$A:$A,MATCH(4,calc!$E:$E,0)),"")}
A9: =IF($H9="","",LEFT($H9,FIND("|",$H9)-1)) | B9: =IF($H9="","",MID($H9,FIND("|",$H9)+1,50)) | C9: =IF($H9="","",SUMIF(calc!$A:$A,$H9,calc!$C:$C)) | D9: =IF($H9="","",ROUNDUP($C9*Spares!$B$3,0)) | E9: =IF($H9="","",$C9+$D9) | H9: {=IFERROR(INDEX(calc!$A:$A,MATCH(5,calc!$E:$E,0)),"")}
A10: =IF($H10="","",LEFT($H10,FIND("|",$H10)-1)) | B10: =IF($H10="","",MID($H10,FIND("|",$H10)+1,50)) | C10: =IF($H10="","",SUMIF(calc!$A:$A,$H10,calc!$C:$C)) | D10: =IF($H10="","",ROUNDUP($C10*Spares!$B$3,0)) | E10: =IF($H10="","",$C10+$D10) | H10: {=IFERROR(INDEX(calc!$A:$A,MATCH(6,calc!$E:$E,0)),"")}
A11: =IF($H11="","",LEFT($H11,FIND("|",$H11)-1)) | B11: =IF($H11="","",MID($H11,FIND("|",$H11)+1,50)) | C11: =IF($H11="","",SUMIF(calc!$A:$A,$H11,calc!$C:$C)) | D11: =IF($H11="","",ROUNDUP($C11*Spares!$B$3,0)) | E11: =IF($H11="","",$C11+$D11) | H11: {=IFERROR(INDEX(calc!$A:$A,MATCH(7,calc!$E:$E,0)),"")}
A12: =IF($H12="","",LEFT($H12,FIND("|",$H12)-1)) | B12: =IF($H12="","",MID($H12,FIND("|",$H12)+1,50)) | C12: =IF($H12="","",SUMIF(calc!$A:$A,$H12,calc!$C:$C)) | D12: =IF($H12="","",ROUNDUP($C12*Spares!$B$3,0)) | E12: =IF($H12="","",$C12+$D12) | H12: {=IFERROR(INDEX(calc!$A:$A,MATCH(8,calc!$E:$E,0)),"")}
A13: =IF($H13="","",LEFT($H13,FIND("|",$H13)-1)) | B13: =IF($H13="","",MID($H13,FIND("|",$H13)+1,50)) | C13: =IF($H13="","",SUMIF(calc!$A:$A,$H13,calc!$C:$C)) | D13: =IF($H13="","",ROUNDUP($C13*Spares!$B$3,0)) | E13: =IF($H13="","",$C13+$D13) | H13: {=IFERROR(INDEX(calc!$A:$A,MATCH(9,calc!$E:$E,0)),"")}
A14: =IF($H14="","",LEFT($H14,FIND("|",$H14)-1)) | B14: =IF($H14="","",MID($H14,FIND("|",$H14)+1,50)) | C14: =IF($H14="","",SUMIF(calc!$A:$A,$H14,calc!$C:$C)) | D14: =IF($H14="","",ROUNDUP($C14*Spares!$B$3,0)) | E14: =IF($H14="","",$C14+$D14) | H14: {=IFERROR(INDEX(calc!$A:$A,MATCH(10,calc!$E:$E,0)),"")}
A15: =IF($H15="","",LEFT($H15,FIND("|",$H15)-1)) | B15: =IF($H15="","",MID($H15,FIND("|",$H15)+1,50)) | C15: =IF($H15="","",SUMIF(calc!$A:$A,$H15,calc!$C:$C)) | D15: =IF($H15="","",ROUNDUP($C15*Spares!$B$3,0)) | E15: =IF($H15="","",$C15+$D15) | H15: {=IFERROR(INDEX(calc!$A:$A,MATCH(11,calc!$E:$E,0)),"")}
A16: =IF($H16="","",LEFT($H16,FIND("|",$H16)-1)) | B16: =IF($H16="","",MID($H16,FIND("|",$H16)+1,50)) | C16: =IF($H16="","",SUMIF(calc!$A:$A,$H16,calc!$C:$C)) | D16: =IF($H16="","",ROUNDUP($C16*Spares!$B$3,0)) | E16: =IF($H16="","",$C16+$D16) | H16: {=IFERROR(INDEX(calc!$A:$A,MATCH(12,calc!$E:$E,0)),"")}
A17: =IF($H17="","",LEFT($H17,FIND("|",$H17)-1)) | B17: =IF($H17="","",MID($H17,FIND("|",$H17)+1,50)) | C17: =IF($H17="","",SUMIF(calc!$A:$A,$H17,calc!$C:$C)) | D17: =IF($H17="","",ROUNDUP($C17*Spares!$B$3,0)) | E17: =IF($H17="","",$C17+$D17) | H17: {=IFERROR(INDEX(calc!$A:$A,MATCH(13,calc!$E:$E,0)),"")}
A18: =IF($H18="","",LEFT($H18,FIND("|",$H18)-1)) | B18: =IF($H18="","",MID($H18,FIND("|",$H18)+1,50)) | C18: =IF($H18="","",SUMIF(calc!$A:$A,$H18,calc!$C:$C)) | D18: =IF($H18="","",ROUNDUP($C18*Spares!$B$3,0)) | E18: =IF($H18="","",$C18+$D18) | H18: {=IFERROR(INDEX(calc!$A:$A,MATCH(14,calc!$E:$E,0)),"")}
A19: =IF($H19="","",LEFT($H19,FIND("|",$H19)-1)) | B19: =IF($H19="","",MID($H19,FIND("|",$H19)+1,50)) | C19: =IF($H19="","",SUMIF(calc!$A:$A,$H19,calc!$C:$C)) | D19: =IF($H19="","",ROUNDUP($C19*Spares!$B$3,0)) | E19: =IF($H19="","",$C19+$D19) | H19: {=IFERROR(INDEX(calc!$A:$A,MATCH(15,calc!$E:$E,0)),"")}
A20: =IF($H20="","",LEFT($H20,FIND("|",$H20)-1)) | B20: =IF($H20="","",MID($H20,FIND("|",$H20)+1,50)) | C20: =IF($H20="","",SUMIF(calc!$A:$A,$H20,calc!$C:$C)) | D20: =IF($H20="","",ROUNDUP($C20*Spares!$B$3,0)) | E20: =IF($H20="","",$C20+$D20) | H20: {=IFERROR(INDEX(calc!$A:$A,MATCH(16,calc!$E:$E,0)),"")}
A21: =IF($H21="","",LEFT($H21,FIND("|",$H21)-1)) | B21: =IF($H21="","",MID($H21,FIND("|",$H21)+1,50)) | C21: =IF($H21="","",SUMIF(calc!$A:$A,$H21,calc!$C:$C)) | D21: =IF($H21="","",ROUNDUP($C21*Spares!$B$3,0)) | E21: =IF($H21="","",$C21+$D21) | H21: {=IFERROR(INDEX(calc!$A:$A,MATCH(17,calc!$E:$E,0)),"")}
A22: =IF($H22="","",LEFT($H22,FIND("|",$H22)-1)) | B22: =IF($H22="","",MID($H22,FIND("|",$H22)+1,50)) | C22: =IF($H22="","",SUMIF(calc!$A:$A,$H22,calc!$C:$C)) | D22: =IF($H22="","",ROUNDUP($C22*Spares!$B$3,0)) | E22: =IF($H22="","",$C22+$D22) | H22: {=IFERROR(INDEX(calc!$A:$A,MATCH(18,calc!$E:$E,0)),"")}
A23: =IF($H23="","",LEFT($H23,FIND("|",$H23)-1)) | B23: =IF($H23="","",MID($H23,FIND("|",$H23)+1,50)) | C23: =IF($H23="","",SUMIF(calc!$A:$A,$H23,calc!$C:$C)) | D23: =IF($H23="","",ROUNDUP($C23*Spares!$B$3,0)) | E23: =IF($H23="","",$C23+$D23) | H23: {=IFERROR(INDEX(calc!$A:$A,MATCH(19,calc!$E:$E,0)),"")}
A24: =IF($H24="","",LEFT($H24,FIND("|",$H24)-1)) | B24: =IF($H24="","",MID($H24,FIND("|",$H24)+1,50)) | C24: =IF($H24="","",SUMIF(calc!$A:$A,$H24,calc!$C:$C)) | D24: =IF($H24="","",ROUNDUP($C24*Spares!$B$3,0)) | E24: =IF($H24="","",$C24+$D24) | H24: {=IFERROR(INDEX(calc!$A:$A,MATCH(20,calc!$E:$E,0)),"")}
A25: =IF($H25="","",LEFT($H25,FIND("|",$H25)-1)) | B25: =IF($H25="","",MID($H25,FIND("|",$H25)+1,50)) | C25: =IF($H25="","",SUMIF(calc!$A:$A,$H25,calc!$C:$C)) | D25: =IF($H25="","",ROUNDUP($C25*Spares!$B$3,0)) | E25: =IF($H25="","",$C25+$D25) | H25: {=IFERROR(INDEX(calc!$A:$A,MATCH(21,calc!$E:$E,0)),"")}
A26: =IF($H26="","",LEFT($H26,FIND("|",$H26)-1)) | B26: =IF($H26="","",MID($H26,FIND("|",$H26)+1,50)) | C26: =IF($H26="","",SUMIF(calc!$A:$A,$H26,calc!$C:$C)) | D26: =IF($H26="","",ROUNDUP($C26*Spares!$B$3,0)) | E26: =IF($H26="","",$C26+$D26) | H26: {=IFERROR(INDEX(calc!$A:$A,MATCH(22,calc!$E:$E,0)),"")}
A27: =IF($H27="","",LEFT($H27,FIND("|",$H27)-1)) | B27: =IF($H27="","",MID($H27,FIND("|",$H27)+1,50)) | C27: =IF($H27="","",SUMIF(calc!$A:$A,$H27,calc!$C:$C)) | D27: =IF($H27="","",ROUNDUP($C27*Spares!$B$3,0)) | E27: =IF($H27="","",$C27+$D27) | H27: {=IFERROR(INDEX(calc!$A:$A,MATCH(23,calc!$E:$E,0)),"")}
A28: =IF($H28="","",LEFT($H28,FIND("|",$H28)-1)) | B28: =IF($H28="","",MID($H28,FIND("|",$H28)+1,50)) | C28: =IF($H28="","",SUMIF(calc!$A:$A,$H28,calc!$C:$C)) | D28: =IF($H28="","",ROUNDUP($C28*Spares!$B$3,0)) | E28: =IF($H28="","",$C28+$D28) | H28: {=IFERROR(INDEX(calc!$A:$A,MATCH(24,calc!$E:$E,0)),"")}
A29: =IF($H29="","",LEFT($H29,FIND("|",$H29)-1)) | B29: =IF($H29="","",MID($H29,FIND("|",$H29)+1,50)) | C29: =IF($H29="","",SUMIF(calc!$A:$A,$H29,calc!$C:$C)) | D29: =IF($H29="","",ROUNDUP($C29*Spares!$B$3,0)) | E29: =IF($H29="","",$C29+$D29) | H29: {=IFERROR(INDEX(calc!$A:$A,MATCH(25,calc!$E:$E,0)),"")}
A30: =IF($H30="","",LEFT($H30,FIND("|",$H30)-1)) | B30: =IF($H30="","",MID($H30,FIND("|",$H30)+1,50)) | C30: =IF($H30="","",SUMIF(calc!$A:$A,$H30,calc!$C:$C)) | D30: =IF($H30="","",ROUNDUP($C30*Spares!$B$3,0)) | E30: =IF($H30="","",$C30+$D30) | H30: {=IFERROR(INDEX(calc!$A:$A,MATCH(26,calc!$E:$E,0)),"")}
A31: =IF($H31="","",LEFT($H31,FIND("|",$H31)-1)) | B31: =IF($H31="","",MID($H31,FIND("|",$H31)+1,50)) | C31: =IF($H31="","",SUMIF(calc!$A:$A,$H31,calc!$C:$C)) | D31: =IF($H31="","",ROUNDUP($C31*Spares!$B$3,0)) | E31: =IF($H31="","",$C31+$D31) | H31: {=IFERROR(INDEX(calc!$A:$A,MATCH(27,calc!$E:$E,0)),"")}
A32: =IF($H32="","",LEFT($H32,FIND("|",$H32)-1)) | B32: =IF($H32="","",MID($H32,FIND("|",$H32)+1,50)) | C32: =IF($H32="","",SUMIF(calc!$A:$A,$H32,calc!$C:$C)) | D32: =IF($H32="","",ROUNDUP($C32*Spares!$B$3,0)) | E32: =IF($H32="","",$C32+$D32) | H32: {=IFERROR(INDEX(calc!$A:$A,MATCH(28,calc!$E:$E,0)),"")}
A33: =IF($H33="","",LEFT($H33,FIND("|",$H33)-1)) | B33: =IF($H33="","",MID($H33,FIND("|",$H33)+1,50)) | C33: =IF($H33="","",SUMIF(calc!$A:$A,$H33,calc!$C:$C)) | D33: =IF($H33="","",ROUNDUP($C33*Spares!$B$3,0)) | E33: =IF($H33="","",$C33+$D33) | H33: {=IFERROR(INDEX(calc!$A:$A,MATCH(29,calc!$E:$E,0)),"")}
A34: =IF($H34="","",LEFT($H34,FIND("|",$H34)-1)) | B34: =IF($H34="","",MID($H34,FIND("|",$H34)+1,50)) | C34: =IF($H34="","",SUMIF(calc!$A:$A,$H34,calc!$C:$C)) | D34: =IF($H34="","",ROUNDUP($C34*Spares!$B$3,0)) | E34: =IF($H34="","",$C34+$D34) | H34: {=IFERROR(INDEX(calc!$A:$A,MATCH(30,calc!$E:$E,0)),"")}
A35: =IF($H35="","",LEFT($H35,FIND("|",$H35)-1)) | B35: =IF($H35="","",MID($H35,FIND("|",$H35)+1,50)) | C35: =IF($H35="","",SUMIF(calc!$A:$A,$H35,calc!$C:$C)) | D35: =IF($H35="","",ROUNDUP($C35*Spares!$B$3,0)) | E35: =IF($H35="","",$C35+$D35) | H35: {=IFERROR(INDEX(calc!$A:$A,MATCH(31,calc!$E:$E,0)),"")}
A36: =IF($H36="","",LEFT($H36,FIND("|",$H36)-1)) | B36: =IF($H36="","",MID($H36,FIND("|",$H36)+1,50)) | C36: =IF($H36="","",SUMIF(calc!$A:$A,$H36,calc!$C:$C)) | D36: =IF($H36="","",ROUNDUP($C36*Spares!$B$3,0)) | E36: =IF($H36="","",$C36+$D36) | H36: {=IFERROR(INDEX(calc!$A:$A,MATCH(32,calc!$E:$E,0)),"")}
A37: =IF($H37="","",LEFT($H37,FIND("|",$H37)-1)) | B37: =IF($H37="","",MID($H37,FIND("|",$H37)+1,50)) | C37: =IF($H37="","",SUMIF(calc!$A:$A,$H37,calc!$C:$C)) | D37: =IF($H37="","",ROUNDUP($C37*Spares!$B$3,0)) | E37: =IF($H37="","",$C37+$D37) | H37: {=IFERROR(INDEX(calc!$A:$A,MATCH(33,calc!$E:$E,0)),"")}
A38: =IF($H38="","",LEFT($H38,FIND("|",$H38)-1)) | B38: =IF($H38="","",MID($H38,FIND("|",$H38)+1,50)) | C38: =IF($H38="","",SUMIF(calc!$A:$A,$H38,calc!$C:$C)) | D38: =IF($H38="","",ROUNDUP($C38*Spares!$B$3,0)) | E38: =IF($H38="","",$C38+$D38) | H38: {=IFERROR(INDEX(calc!$A:$A,MATCH(34,calc!$E:$E,0)),"")}
A39: =IF($H39="","",LEFT($H39,FIND("|",$H39)-1)) | B39: =IF($H39="","",MID($H39,FIND("|",$H39)+1,50)) | C39: =IF($H39="","",SUMIF(calc!$A:$A,$H39,calc!$C:$C)) | D39: =IF($H39="","",ROUNDUP($C39*Spares!$B$3,0)) | E39: =IF($H39="","",$C39+$D39) | H39: {=IFERROR(INDEX(calc!$A:$A,MATCH(35,calc!$E:$E,0)),"")}
A40: =IF($H40="","",LEFT($H40,FIND("|",$H40)-1)) | B40: =IF($H40="","",MID($H40,FIND("|",$H40)+1,50)) | C40: =IF($H40="","",SUMIF(calc!$A:$A,$H40,calc!$C:$C)) | D40: =IF($H40="","",ROUNDUP($C40*Spares!$B$3,0)) | E40: =IF($H40="","",$C40+$D40) | H40: {=IFERROR(INDEX(calc!$A:$A,MATCH(36,calc!$E:$E,0)),"")}
A41: =IF($H41="","",LEFT($H41,FIND("|",$H41)-1)) | B41: =IF($H41="","",MID($H41,FIND("|",$H41)+1,50)) | C41: =IF($H41="","",SUMIF(calc!$A:$A,$H41,calc!$C:$C)) | D41: =IF($H41="","",ROUNDUP($C41*Spares!$B$3,0)) | E41: =IF($H41="","",$C41+$D41) | H41: {=IFERROR(INDEX(calc!$A:$A,MATCH(37,calc!$E:$E,0)),"")}
...

Sheet GEAR LIST
A1: GEAR LIST
A2: Add gear here. Type a new cable in column A or a length in column B and it shows up in the Pull Sheet dropdowns automatically.
A3: Cable Types | B3: Lengths
A4: Tru-1 Breakout | B4: EA
A5: Ether-con Snake | B5: 3'
A6: Ether-con | B6: 4'
A7: Ether-con Barrel | B7: 5'
A8: Tru-1 | B8: 6'
A9: Multi | B9: 10'
A10: 12G SDI | B10: 15'
A11: HDMI | B11: 25'
A12: Ethernet | B12: 50'
A13: P14 | B13: 75'
A14: Absen TRU-1 Long Power Jump | B14: 100'
... A20: Header Triple | B20: 500'
A21: Header Double
A22: Header Single
A23: 3G SDI
A24: H5
A25: 16 port sending card + 2 OPT
A26: CVT Rack
A27: 12 Tac Fiber
A28: 10G Single-Mode SFP
A29: UHD JR

Sheet READ ME
B2: LED CABLE PULL SHEET - how it works
B5: LAYOUT
B6: Positions sit SIDE BY SIDE across the sheet (first three, then the tan copy-me block).
B7: Scroll right for more room instead of down. All positions share the same rows.
B9: DYNAMIC
B10: TOTALS and Spares build themselves from every position. Type any cable + length + qty and
B11: it appears; delete it and it drops off. The same cable across positions merges to one line.
B13: ADD / CHANGE GEAR IN THE DROPDOWNS
B14: GEAR LIST tab: type a new cable under 'Cable Types' or a length under 'Lengths'. It shows up
B15: in the Pull Sheet dropdowns right away. Dropdowns only warn, never block.
B17: ADD MORE ROWS
B18: Each position has 30 rows. Need more? Select some data-row numbers, right-click > Insert N
... B44: TOTALS and Spares sort themselves automatically - no button needed there.

Sheet calc
A1: key (type|length) | B1: rank | C1: qty | D1: sortkey | E1: sortrank
A5: {=IF(N(INDIRECT("'Pull Sheet'!C7"))>0,INDIRECT("'Pull Sheet'!A7")&"|"&INDIRECT("'Pull Sheet'!B7"),"")} | B5: =IF(AND($A5<>"",COUNTIF($A$5:$A5,$A5)=1),MAX($B$4:$B4)+1,"") | C5: {=IF($A5="","",N(INDIRECT("'Pull Sheet'!C7")))} | D5: =IF($B5="","",IF(IFERROR(VALUE(LEFT(LOWER(LEFT($A5,FIND("|",$A5)-1)),3)),IFERROR(VALUE(LEFT(LOWER(LEFT($A5,FIND("|",$A5)-1)),2)),IFERROR(VALUE(LEFT(LOWER(LEFT($A5,FIND("|",$A5)-1)),1)),-1)))>=0,TEXT(IFERROR(VALUE(LEFT(LOWER(LEFT($A5,FIND("|",$A5)-1)),3)),IFERROR(VALUE(LEFT(LOWER(LEFT($A5,FIND("|",$A5)-1)),2)),IFERROR(VALUE(LEFT(LOWER(LEFT($A5,FIND("|",$A5)-1)),1)),-1))),"000000")&MID(LOWER(LEFT($A5,FIND("|",$A5)-1)),LEN(TEXT(IFERROR(VALUE(LEFT(LOWER(LEFT($A5,FIND("|",$A5)-1)),3)),IFERROR(VALUE(LEFT(LOWER(LEFT($A5,FIND("|",$A5)-1)),2)),IFERROR(VALUE(LEFT(LOWER(LEFT($A5,FIND("|",$A5)-1)),1)),-1))),"0"))+1,99),LOWER(LEFT($A5,FIND("|",$A5)-1)))&CHAR(9)&TEXT(IF(SUBSTITUTE(MID($A5,FIND("|",$A5)+1,50),"'","")="",0,IFERROR(VALUE(SUBSTITUTE(MID($A5,FIND("|",$A5)+1,50),"'","")),999999)),"000000")&CHAR(9)&TEXT($B5,"0000")) | E5: =IF($D5="","",SUMPRODUCT(($D$5:$D$364<>"")*($D$5:$D$364<$D5))+1)
A6: {=IF(N(INDIRECT("'Pull Sheet'!C8"))>0,INDIRECT("'Pull Sheet'!A8")&"|"&INDIRECT("'Pull Sheet'!B8"),"")} | B6: =IF(AND($A6<>"",COUNTIF($A$5:$A6,$A6)=1),MAX($B$4:$B5)+1,"") | C6: {=IF($A6="","",N(INDIRECT("'Pull Sheet'!C8")))} | D6: =IF($B6="","",IF(IFERROR(VALUE(LEFT(LOWER(LEFT($A6,FIND("|",$A6)-1)),3)),IFERROR(VALUE(LEFT(LOWER(LEFT($A6,FIND("|",$A6)-1)),2)),IFERROR(VALUE(LEFT(LOWER(LEFT($A6,FIND("|",$A6)-1)),1)),-1)))>=0,TEXT(IFERROR(VALUE(LEFT(LOWER(LEFT($A6,FIND("|",$A6)-1)),3)),IFERROR(VALUE(LEFT(LOWER(LEFT($A6,FIND("|",$A6)-1)),2)),IFERROR(VALUE(LEFT(LOWER(LEFT($A6,FIND("|",$A6)-1)),1)),-1))),"000000")&MID(LOWER(LEFT($A6,FIND("|",$A6)-1)),LEN(TEXT(IFERROR(VALUE(LEFT(LOWER(LEFT($A6,FIND("|",$A6)-1)),3)),IFERROR(VALUE(LEFT(LOWER(LEFT($A6,FIND("|",$A6)-1)),2)),IFERROR(VALUE(LEFT(LOWER(LEFT($A6,FIND("|",$A6)-1)),1)),-1))),"0"))+1,99),LOWER(LEFT($A6,FIND("|",$A6)-1)))&CHAR(9)&TEXT(IF(SUBSTITUTE(MID($A6,FIND("|",$A6)+1,50),"'","")="",0,IFERROR(VALUE(SUBSTITUTE(MID($A6,FIND("|",$A6)+1,50),"'","")),999999)),"000000")&CHAR(9)&TEXT($B6,"0000")) | E6: =IF($D6="","",SUMPRODUCT(($D$5:$D$364<>"")*($D$5:$D$364<$D6))+1)
A7: {=IF(N(INDIRECT("'Pull Sheet'!C9"))>0,INDIRECT("'Pull Sheet'!A9")&"|"&INDIRECT("'Pull Sheet'!B9"),"")} | B7: =IF(AND($A7<>"",COUNTIF($A$5:$A7,$A7)=1),MAX($B$4:$B6)+1,"") | C7: {=IF($A7="","",N(INDIRECT("'Pull Sheet'!C9")))} | D7: =IF($B7="","",IF(IFERROR(VALUE(LEFT(LOWER(LEFT($A7,FIND("|",$A7)-1)),3)),IFERROR(VALUE(LEFT(LOWER(LEFT($A7,FIND("|",$A7)-1)),2)),IFERROR(VALUE(LEFT(LOWER(LEFT($A7,FIND("|",$A7)-1)),1)),-1)))>=0,TEXT(IFERROR(VALUE(LEFT(LOWER(LEFT($A7,FIND("|",$A7)-1)),3)),IFERROR(VALUE(LEFT(LOWER(LEFT($A7,FIND("|",$A7)-1)),2)),IFERROR(VALUE(LEFT(LOWER(LEFT($A7,FIND("|",$A7)-1)),1)),-1))),"000000")&MID(LOWER(LEFT($A7,FIND("|",$A7)-1)),LEN(TEXT(IFERROR(VALUE(LEFT(LOWER(LEFT($A7,FIND("|",$A7)-1)),3)),IFERROR(VALUE(LEFT(LOWER(LEFT($A7,FIND("|",$A7)-1)),2)),IFERROR(VALUE(LEFT(LOWER(LEFT($A7,FIND("|",$A7)-1)),1)),-1))),"0"))+1,99),LOWER(LEFT($A7,FIND("|",$A7)-1)))&CHAR(9)&TEXT(IF(SUBSTITUTE(MID($A7,FIND("|",$A7)+1,50),"'","")="",0,IFERROR(VALUE(SUBSTITUTE(MID($A7,FIND("|",$A7)+1,50),"'","")),999999)),"000000")&CHAR(9)&TEXT($B7,"0000")) | E7: =IF($D7="","",SUMPRODUCT(($D$5:$D$364<>"")*($D$5:$D$364<$D7))+1)
A8: {=IF(N(INDIRECT("'Pull Sheet'!C10"))>0,INDIRECT("'Pull Sheet'!A10")&"|"&INDIRECT("'Pull Sheet'!B10"),"")} | B8: =IF(AND($A8<>"",COUNTIF($A$5:$A8,$A8)=1),MAX($B$4:$B7)+1,"") | C8: {=IF($A8="","",N(INDIRECT("'Pull Sheet'!C10")))} | D8: =IF($B8="","",IF(IFERROR(VALUE(LEFT(LOWER(LEFT($A8,FIND("|",$A8)-1)),3)),IFERROR(VALUE(LEFT(LOWER(LEFT($A8,FIND("|",$A8)-1)),2)),IFERROR(VALUE(LEFT(LOWER(LEFT($A8,FIND("|",$A8)-1)),1)),-1)))>=0,TEXT(IFERROR(VALUE(LEFT(LOWER(LEFT($A8,FIND("|",$A8)-1)),3)),IFERROR(VALUE(LEFT(LOWER(LEFT($A8,FIND("|",$A8)-1)),2)),IFERROR(VALUE(LEFT(LOWER(LEFT($A8,FIND("|",$A8)-1)),1)),-1))),"000000")&MID(LOWER(LEFT($A8,FIND("|",$A8)-1)),LEN(TEXT(IFERROR(VALUE(LEFT(LOWER(LEFT($A8,FIND("|",$A8)-1)),3)),IFERROR(VALUE(LEFT(LOWER(LEFT($A8,FIND("|",$A8)-1)),2)),IFERROR(VALUE(LEFT(LOWER(LEFT($A8,FIND("|",$A8)-1)),1)),-1))),"0"))+1,99),LOWER(LEFT($A8,FIND("|",$A8)-1)))&CHAR(9)&TEXT(IF(SUBSTITUTE(MID($A8,FIND("|",$A8)+1,50),"'","")="",0,IFERROR(VALUE(SUBSTITUTE(MID($A8,FIND("|",$A8)+1,50),"'","")),999999)),"000000")&CHAR(9)&TEXT($B8,"0000")) | E8: =IF($D8="","",SUMPRODUCT(($D$5:$D$364<>"")*($D$5:$D$364<$D8))+1)
A9: {=IF(N(INDIRECT("'Pull Sheet'!C11"))>0,INDIRECT("'Pull Sheet'!A11")&"|"&INDIRECT("'Pull Sheet'!B11"),"")} | B9: =IF(AND($A9<>"",COUNTIF($A$5:$A9,$A9)=1),MAX($B$4:$B8)+1,"") | C9: {=IF($A9="","",N(INDIRECT("'Pull Sheet'!C11")))} | D9: =IF($B9="","",IF(IFERROR(VALUE(LEFT(LOWER(LEFT($A9,FIND("|",$A9)-1)),3)),IFERROR(VALUE(LEFT(LOWER(LEFT($A9,FIND("|",$A9)-1)),2)),IFERROR(VALUE(LEFT(LOWER(LEFT($A9,FIND("|",$A9)-1)),1)),-1)))>=0,TEXT(IFERROR(VALUE(LEFT(LOWER(LEFT($A9,FIND("|",$A9)-1)),3)),IFERROR(VALUE(LEFT(LOWER(LEFT($A9,FIND("|",$A9)-1)),2)),IFERROR(VALUE(LEFT(LOWER(LEFT($A9,FIND("|",$A9)-1)),1)),-1))),"000000")&MID(LOWER(LEFT($A9,FIND("|",$A9)-1)),LEN(TEXT(IFERROR(VALUE(LEFT(LOWER(LEFT($A9,FIND("|",$A9)-1)),3)),IFERROR(VALUE(LEFT(LOWER(LEFT($A9,FIND("|",$A9)-1)),2)),IFERROR(VALUE(LEFT(LOWER(LEFT($A9,FIND("|",$A9)-1)),1)),-1))),"0"))+1,99),LOWER(LEFT($A9,FIND("|",$A9)-1)))&CHAR(9)&TEXT(IF(SUBSTITUTE(MID($A9,FIND("|",$A9)+1,50),"'","")="",0,IFERROR(VALUE(SUBSTITUTE(MID($A9,FIND("|",$A9)+1,50),"'","")),999999)),"000000")&CHAR(9)&TEXT($B9,"0000")) | E9: =IF($D9="","",SUMPRODUCT(($D$5:$D$364<>"")*($D$5:$D$364<$D9))+1)
A10: {=IF(N(INDIRECT("'Pull Sheet'!C12"))>0,INDIRECT("'Pull Sheet'!A12")&"|"&INDIRECT("'Pull Sheet'!B12"),"")} | B10: =IF(AND($A10<>"",COUNTIF($A$5:$A10,$A10)=1),MAX($B$4:$B9)+1,"") | C10: {=IF($A10="","",N(INDIRECT("'Pull Sheet'!C12")))} | D10: =IF($B10="","",IF(IFERROR(VALUE(LEFT(LOWER(LEFT($A10,FIND("|",$A10)-1)),3)),IFERROR(VALUE(LEFT(LOWER(LEFT($A10,FIND("|",$A10)-1)),2)),IFERROR(VALUE(LEFT(LOWER(LEFT($A10,FIND("|",$A10)-1)),1)),-1)))>=0,TEXT(IFERROR(VALUE(LEFT(LOWER(LEFT($A10,FIND("|",$A10)-1)),3)),IFERROR(VALUE(LEFT(LOWER(LEFT($A10,FIND("|",$A10)-1)),2)),IFERROR(VALUE(LEFT(LOWER(LEFT($A10,FIND("|",$A10)-1)),1)),-1))),"000000")&MID(LOWER(LEFT($A10,FIND("|",$A10)-1)),LEN(TEXT(IFERROR(VALUE(LEFT(LOWER(LEFT($A10,FIND("|",$A10)-1)),3)),IFERROR(VALUE(LEFT(LOWER(LEFT($A10,FIND("|",$A10)-1)),2)),IFERROR(VALUE(LEFT(LOWER(LEFT($A10,FIND("|",$A10)-1)),1)),-1))),"0"))+1,99),LOWER(LEFT($A10,FIND("|",$A10)-1)))&CHAR(9)&TEXT(IF(SUBSTITUTE(MID($A10,FIND("|",$A10)+1,50),"'","")="",0,IFERROR(VALUE(SUBSTITUTE(MID($A10,FIND("|",$A10)+1,50),"'","")),999999)),"000000")&CHAR(9)&TEXT($B10,"0000")) | E10: =IF($D10="","",SUMPRODUCT(($D$5:$D$364<>"")*($D$5:$D$364<$D10))+1)
A11: {=IF(N(INDIRECT("'Pull Sheet'!C13"))>0,INDIRECT("'Pull Sheet'!A13")&"|"&INDIRECT("'Pull Sheet'!B13"),"")} | B11: =IF(AND($A11<>"",COUNTIF($A$5:$A11,$A11)=1),MAX($B$4:$B10)+1,"") | C11: {=IF($A11="","",N(INDIRECT("'Pull Sheet'!C13")))} | D11: =IF($B11="","",IF(IFERROR(VALUE(LEFT(LOWER(LEFT($A11,FIND("|",$A11)-1)),3)),IFERROR(VALUE(LEFT(LOWER(LEFT($A11,FIND("|",$A11)-1)),2)),IFERROR(VALUE(LEFT(LOWER(LEFT($A11,FIND("|",$A11)-1)),1)),-1)))>=0,TEXT(IFERROR(VALUE(LEFT(LOWER(LEFT($A11,FIND("|",$A11)-1)),3)),IFERROR(VALUE(LEFT(LOWER(LEFT($A11,FIND("|",$A11)-1)),2)),IFERROR(VALUE(LEFT(LOWER(LEFT($A11,FIND("|",$A11)-1)),1)),-1))),"000000")&MID(LOWER(LEFT($A11,FIND("|",$A11)-1)),LEN(TEXT(IFERROR(VALUE(LEFT(LOWER(LEFT($A11,FIND("|",$A11)-1)),3)),IFERROR(VALUE(LEFT(LOWER(LEFT($A11,FIND("|",$A11)-1)),2)),IFERROR(VALUE(LEFT(LOWER(LEFT($A11,FIND("|",$A11)-1)),1)),-1))),"0"))+1,99),LOWER(LEFT($A11,FIND("|",$A11)-1)))&CHAR(9)&TEXT(IF(SUBSTITUTE(MID($A11,FIND("|",$A11)+1,50),"'","")="",0,IFERROR(VALUE(SUBSTITUTE(MID($A11,FIND("|",$A11)+1,50),"'","")),999999)),"000000")&CHAR(9)&TEXT($B11,"0000")) | E11: =IF($D11="","",SUMPRODUCT(($D$5:$D$364<>"")*($D$5:$D$364<$D11))+1)
A12: {=IF(N(INDIRECT("'Pull Sheet'!C14"))>0,INDIRECT("'Pull Sheet'!A14")&"|"&INDIRECT("'Pull Sheet'!B14"),"")} | B12: =IF(AND($A12<>"",COUNTIF($A$5:$A12,$A12)=1),MAX($B$4:$B11)+1,"") | C12: {=IF($A12="","",N(INDIRECT("'Pull Sheet'!C14")))} | D12: =IF($B12="","",IF(IFERROR(VALUE(LEFT(LOWER(LEFT($A12,FIND("|",$A12)-1)),3)),IFERROR(VALUE(LEFT(LOWER(LEFT($A12,FIND("|",$A12)-1)),2)),IFERROR(VALUE(LEFT(LOWER(LEFT($A12,FIND("|",$A12)-1)),1)),-1)))>=0,TEXT(IFERROR(VALUE(LEFT(LOWER(LEFT($A12,FIND("|",$A12)-1)),3)),IFERROR(VALUE(LEFT(LOWER(LEFT($A12,FIND("|",$A12)-1)),2)),IFERROR(VALUE(LEFT(LOWER(LEFT($A12,FIND("|",$A12)-1)),1)),-1))),"000000")&MID(LOWER(LEFT($A12,FIND("|",$A12)-1)),LEN(TEXT(IFERROR(VALUE(LEFT(LOWER(LEFT($A12,FIND("|",$A12)-1)),3)),IFERROR(VALUE(LEFT(LOWER(LEFT($A12,FIND("|",$A12)-1)),2)),IFERROR(VALUE(LEFT(LOWER(LEFT($A12,FIND("|",$A12)-1)),1)),-1))),"0"))+1,99),LOWER(LEFT($A12,FIND("|",$A12)-1)))&CHAR(9)&TEXT(IF(SUBSTITUTE(MID($A12,FIND("|",$A12)+1,50),"'","")="",0,IFERROR(VALUE(SUBSTITUTE(MID($A12,FIND("|",$A12)+1,50),"'","")),999999)),"000000")&CHAR(9)&TEXT($B12,"0000")) | E12: =IF($D12="","",SUMPRODUCT(($D$5:$D$364<>"")*($D$5:$D$364<$D12))+1)
A13: {=IF(N(INDIRECT("'Pull Sheet'!C15"))>0,INDIRECT("'Pull Sheet'!A15")&"|"&INDIRECT("'Pull Sheet'!B15"),"")} | B13: =IF(AND($A13<>"",COUNTIF($A$5:$A13,$A13)=1),MAX($B$4:$B12)+1,"") | C13: {=IF($A13="","",N(INDIRECT("'Pull Sheet'!C15")))} | D13: =IF($B13="","",IF(IFERROR(VALUE(LEFT(LOWER(LEFT($A13,FIND("|",$A13)-1)),3)),IFERROR(VALUE(LEFT(LOWER(LEFT($A13,FIND("|",$A13)-1)),2)),IFERROR(VALUE(LEFT(LOWER(LEFT($A13,FIND("|",$A13)-1)),1)),-1)))>=0,TEXT(IFERROR(VALUE(LEFT(LOWER(LEFT($A13,FIND("|",$A13)-1)),3)),IFERROR(VALUE(LEFT(LOWER(LEFT($A13,FIND("|",$A13)-1)),2)),IFERROR(VALUE(LEFT(LOWER(LEFT($A13,FIND("|",$A13)-1)),1)),-1))),"000000")&MID(LOWER(LEFT($A13,FIND("|",$A13)-1)),LEN(TEXT(IFERROR(VALUE(LEFT(LOWER(LEFT($A13,FIND("|",$A13)-1)),3)),IFERROR(VALUE(LEFT(LOWER(LEFT($A13,FIND("|",$A13)-1)),2)),IFERROR(VALUE(LEFT(LOWER(LEFT($A13,FIND("|",$A13)-1)),1)),-1))),"0"))+1,99),LOWER(LEFT($A13,FIND("|",$A13)-1)))&CHAR(9)&TEXT(IF(SUBSTITUTE(MID($A13,FIND("|",$A13)+1,50),"'","")="",0,IFERROR(VALUE(SUBSTITUTE(MID($A13,FIND("|",$A13)+1,50),"'","")),999999)),"000000")&CHAR(9)&TEXT($B13,"0000")) | E13: =IF($D13="","",SUMPRODUCT(($D$5:$D$364<>"")*($D$5:$D$364<$D13))+1)
A14: {=IF(N(INDIRECT("'Pull Sheet'!C16"))>0,INDIRECT("'Pull Sheet'!A16")&"|"&INDIRECT("'Pull Sheet'!B16"),"")} | B14: =IF(AND($A14<>"",COUNTIF($A$5:$A14,$A14)=1),MAX($B$4:$B13)+1,"") | C14: {=IF($A14="","",N(INDIRECT("'Pull Sheet'!C16")))} | D14: =IF($B14="","",IF(IFERROR(VALUE(LEFT(LOWER(LEFT($A14,FIND("|",$A14)-1)),3)),IFERROR(VALUE(LEFT(LOWER(LEFT($A14,FIND("|",$A14)-1)),2)),IFERROR(VALUE(LEFT(LOWER(LEFT($A14,FIND("|",$A14)-1)),1)),-1)))>=0,TEXT(IFERROR(VALUE(LEFT(LOWER(LEFT($A14,FIND("|",$A14)-1)),3)),IFERROR(VALUE(LEFT(LOWER(LEFT($A14,FIND("|",$A14)-1)),2)),IFERROR(VALUE(LEFT(LOWER(LEFT($A14,FIND("|",$A14)-1)),1)),-1))),"000000")&MID(LOWER(LEFT($A14,FIND("|",$A14)-1)),LEN(TEXT(IFERROR(VALUE(LEFT(LOWER(LEFT($A14,FIND("|",$A14)-1)),3)),IFERROR(VALUE(LEFT(LOWER(LEFT($A14,FIND("|",$A14)-1)),2)),IFERROR(VALUE(LEFT(LOWER(LEFT($A14,FIND("|",$A14)-1)),1)),-1))),"0"))+1,99),LOWER(LEFT($A14,FIND("|",$A14)-1)))&CHAR(9)&TEXT(IF(SUBSTITUTE(MID($A14,FIND("|",$A14)+1,50),"'","")="",0,IFERROR(VALUE(SUBSTITUTE(MID($A14,FIND("|",$A14)+1,50),"'","")),999999)),"000000")&CHAR(9)&TEXT($B14,"0000")) | E14: =IF($D14="","",SUMPRODUCT(($D$5:$D$364<>"")*($D$5:$D$364<$D14))+1)
A15: {=IF(N(INDIRECT("'Pull Sheet'!C17"))>0,INDIRECT("'Pull Sheet'!A17")&"|"&INDIRECT("'Pull Sheet'!B17"),"")} | B15: =IF(AND($A15<>"",COUNTIF($A$5:$A15,$A15)=1),MAX($B$4:$B14)+1,"") | C15: {=IF($A15="","",N(INDIRECT("'Pull Sheet'!C17")))} | D15: =IF($B15="","",IF(IFERROR(VALUE(LEFT(LOWER(LEFT($A15,FIND("|",$A15)-1)),3)),IFERROR(VALUE(LEFT(LOWER(LEFT($A15,FIND("|",$A15)-1)),2)),IFERROR(VALUE(LEFT(LOWER(LEFT($A15,FIND("|",$A15)-1)),1)),-1)))>=0,TEXT(IFERROR(VALUE(LEFT(LOWER(LEFT($A15,FIND("|",$A15)-1)),3)),IFERROR(VALUE(LEFT(LOWER(LEFT($A15,FIND("|",$A15)-1)),2)),IFERROR(VALUE(LEFT(LOWER(LEFT($A15,FIND("|",$A15)-1)),1)),-1))),"000000")&MID(LOWER(LEFT($A15,FIND("|",$A15)-1)),LEN(TEXT(IFERROR(VALUE(LEFT(LOWER(LEFT($A15,FIND("|",$A15)-1)),3)),IFERROR(VALUE(LEFT(LOWER(LEFT($A15,FIND("|",$A15)-1)),2)),IFERROR(VALUE(LEFT(LOWER(LEFT($A15,FIND("|",$A15)-1)),1)),-1))),"0"))+1,99),LOWER(LEFT($A15,FIND("|",$A15)-1)))&CHAR(9)&TEXT(IF(SUBSTITUTE(MID($A15,FIND("|",$A15)+1,50),"'","")="",0,IFERROR(VALUE(SUBSTITUTE(MID($A15,FIND("|",$A15)+1,50),"'","")),999999)),"000000")&CHAR(9)&TEXT($B15,"0000")) | E15: =IF($D15="","",SUMPRODUCT(($D$5:$D$364<>"")*($D$5:$D$364<$D15))+1)
A16: {=IF(N(INDIRECT("'Pull Sheet'!C18"))>0,INDIRECT("'Pull Sheet'!A18")&"|"&INDIRECT("'Pull Sheet'!B18"),"")} | B16: =IF(AND($A16<>"",COUNTIF($A$5:$A16,$A16)=1),MAX($B$4:$B15)+1,"") | C16: {=IF($A16="","",N(INDIRECT("'Pull Sheet'!C18")))} | D16: =IF($B16="","",IF(IFERROR(VALUE(LEFT(LOWER(LEFT($A16,FIND("|",$A16)-1)),3)),IFERROR(VALUE(LEFT(LOWER(LEFT($A16,FIND("|",$A16)-1)),2)),IFERROR(VALUE(LEFT(LOWER(LEFT($A16,FIND("|",$A16)-1)),1)),-1)))>=0,TEXT(IFERROR(VALUE(LEFT(LOWER(LEFT($A16,FIND("|",$A16)-1)),3)),IFERROR(VALUE(LEFT(LOWER(LEFT($A16,FIND("|",$A16)-1)),2)),IFERROR(VALUE(LEFT(LOWER(LEFT($A16,FIND("|",$A16)-1)),1)),-1))),"000000")&MID(LOWER(LEFT($A16,FIND("|",$A16)-1)),LEN(TEXT(IFERROR(VALUE(LEFT(LOWER(LEFT($A16,FIND("|",$A16)-1)),3)),IFERROR(VALUE(LEFT(LOWER(LEFT($A16,FIND("|",$A16)-1)),2)),IFERROR(VALUE(LEFT(LOWER(LEFT($A16,FIND("|",$A16)-1)),1)),-1))),"0"))+1,99),LOWER(LEFT($A16,FIND("|",$A16)-1)))&CHAR(9)&TEXT(IF(SUBSTITUTE(MID($A16,FIND("|",$A16)+1,50),"'","")="",0,IFERROR(VALUE(SUBSTITUTE(MID($A16,FIND("|",$A16)+1,50),"'","")),999999)),"000000")&CHAR(9)&TEXT($B16,"0000")) | E16: =IF($D16="","",SUMPRODUCT(($D$5:$D$364<>"")*($D$5:$D$364<$D16))+1)
A17: {=IF(N(INDIRECT("'Pull Sheet'!C19"))>0,INDIRECT("'Pull Sheet'!A19")&"|"&INDIRECT("'Pull Sheet'!B19"),"")} | B17: =IF(AND($A17<>"",COUNTIF($A$5:$A17,$A17)=1),MAX($B$4:$B16)+1,"") | C17: {=IF($A17="","",N(INDIRECT("'Pull Sheet'!C19")))} | D17: =IF($B17="","",IF(IFERROR(VALUE(LEFT(LOWER(LEFT($A17,FIND("|",$A17)-1)),3)),IFERROR(VALUE(LEFT(LOWER(LEFT($A17,FIND("|",$A17)-1)),2)),IFERROR(VALUE(LEFT(LOWER(LEFT($A17,FIND("|",$A17)-1)),1)),-1)))>=0,TEXT(IFERROR(VALUE(LEFT(LOWER(LEFT($A17,FIND("|",$A17)-1)),3)),IFERROR(VALUE(LEFT(LOWER(LEFT($A17,FIND("|",$A17)-1)),2)),IFERROR(VALUE(LEFT(LOWER(LEFT($A17,FIND("|",$A17)-1)),1)),-1))),"000000")&MID(LOWER(LEFT($A17,FIND("|",$A17)-1)),LEN(TEXT(IFERROR(VALUE(LEFT(LOWER(LEFT($A17,FIND("|",$A17)-1)),3)),IFERROR(VALUE(LEFT(LOWER(LEFT($A17,FIND("|",$A17)-1)),2)),IFERROR(VALUE(LEFT(LOWER(LEFT($A17,FIND("|",$A17)-1)),1)),-1))),"0"))+1,99),LOWER(LEFT($A17,FIND("|",$A17)-1)))&CHAR(9)&TEXT(IF(SUBSTITUTE(MID($A17,FIND("|",$A17)+1,50),"'","")="",0,IFERROR(VALUE(SUBSTITUTE(MID($A17,FIND("|",$A17)+1,50),"'","")),999999)),"000000")&CHAR(9)&TEXT($B17,"0000")) | E17: =IF($D17="","",SUMPRODUCT(($D$5:$D$364<>"")*($D$5:$D$364<$D17))+1)
A18: {=IF(N(INDIRECT("'Pull Sheet'!C20"))>0,INDIRECT("'Pull Sheet'!A20")&"|"&INDIRECT("'Pull Sheet'!B20"),"")} | B18: =IF(AND($A18<>"",COUNTIF($A$5:$A18,$A18)=1),MAX($B$4:$B17)+1,"") | C18: {=IF($A18="","",N(INDIRECT("'Pull Sheet'!C20")))} | D18: =IF($B18="","",IF(IFERROR(VALUE(LEFT(LOWER(LEFT($A18,FIND("|",$A18)-1)),3)),IFERROR(VALUE(LEFT(LOWER(LEFT($A18,FIND("|",$A18)-1)),2)),IFERROR(VALUE(LEFT(LOWER(LEFT($A18,FIND("|",$A18)-1)),1)),-1)))>=0,TEXT(IFERROR(VALUE(LEFT(LOWER(LEFT($A18,FIND("|",$A18)-1)),3)),IFERROR(VALUE(LEFT(LOWER(LEFT($A18,FIND("|",$A18)-1)),2)),IFERROR(VALUE(LEFT(LOWER(LEFT($A18,FIND("|",$A18)-1)),1)),-1))),"000000")&MID(LOWER(LEFT($A18,FIND("|",$A18)-1)),LEN(TEXT(IFERROR(VALUE(LEFT(LOWER(LEFT($A18,FIND("|",$A18)-1)),3)),IFERROR(VALUE(LEFT(LOWER(LEFT($A18,FIND("|",$A18)-1)),2)),IFERROR(VALUE(LEFT(LOWER(LEFT($A18,FIND("|",$A18)-1)),1)),-1))),"0"))+1,99),LOWER(LEFT($A18,FIND("|",$A18)-1)))&CHAR(9)&TEXT(IF(SUBSTITUTE(MID($A18,FIND("|",$A18)+1,50),"'","")="",0,IFERROR(VALUE(SUBSTITUTE(MID($A18,FIND("|",$A18)+1,50),"'","")),999999)),"000000")&CHAR(9)&TEXT($B18,"0000")) | E18: =IF($D18="","",SUMPRODUCT(($D$5:$D$364<>"")*($D$5:$D$364<$D18))+1)
A19: {=IF(N(INDIRECT("'Pull Sheet'!C21"))>0,INDIRECT("'Pull Sheet'!A21")&"|"&INDIRECT("'Pull Sheet'!B21"),"")} | B19: =IF(AND($A19<>"",COUNTIF($A$5:$A19,$A19)=1),MAX($B$4:$B18)+1,"") | C19: {=IF($A19="","",N(INDIRECT("'Pull Sheet'!C21")))} | D19: =IF($B19="","",IF(IFERROR(VALUE(LEFT(LOWER(LEFT($A19,FIND("|",$A19)-1)),3)),IFERROR(VALUE(LEFT(LOWER(LEFT($A19,FIND("|",$A19)-1)),2)),IFERROR(VALUE(LEFT(LOWER(LEFT($A19,FIND("|",$A19)-1)),1)),-1)))>=0,TEXT(IFERROR(VALUE(LEFT(LOWER(LEFT($A19,FIND("|",$A19)-1)),3)),IFERROR(VALUE(LEFT(LOWER(LEFT($A19,FIND("|",$A19)-1)),2)),IFERROR(VALUE(LEFT(LOWER(LEFT($A19,FIND("|",$A19)-1)),1)),-1))),"000000")&MID(LOWER(LEFT($A19,FIND("|",$A19)-1)),LEN(TEXT(IFERROR(VALUE(LEFT(LOWER(LEFT($A19,FIND("|",$A19)-1)),3)),IFERROR(VALUE(LEFT(LOWER(LEFT($A19,FIND("|",$A19)-1)),2)),IFERROR(VALUE(LEFT(LOWER(LEFT($A19,FIND("|",$A19)-1)),1)),-1))),"0"))+1,99),LOWER(LEFT($A19,FIND("|",$A19)-1)))&CHAR(9)&TEXT(IF(SUBSTITUTE(MID($A19,FIND("|",$A19)+1,50),"'","")="",0,IFERROR(VALUE(SUBSTITUTE(MID($A19,FIND("|",$A19)+1,50),"'","")),999999)),"000000")&CHAR(9)&TEXT($B19,"0000")) | E19: =IF($D19="","",SUMPRODUCT(($D$5:$D$364<>"")*($D$5:$D$364<$D19))+1)
A20: {=IF(N(INDIRECT("'Pull Sheet'!C22"))>0,INDIRECT("'Pull Sheet'!A22")&"|"&INDIRECT("'Pull Sheet'!B22"),"")} | B20: =IF(AND($A20<>"",COUNTIF($A$5:$A20,$A20)=1),MAX($B$4:$B19)+1,"") | C20: {=IF($A20="","",N(INDIRECT("'Pull Sheet'!C22")))} | D20: =IF($B20="","",IF(IFERROR(VALUE(LEFT(LOWER(LEFT($A20,FIND("|",$A20)-1)),3)),IFERROR(VALUE(LEFT(LOWER(LEFT($A20,FIND("|",$A20)-1)),2)),IFERROR(VALUE(LEFT(LOWER(LEFT($A20,FIND("|",$A20)-1)),1)),-1)))>=0,TEXT(IFERROR(VALUE(LEFT(LOWER(LEFT($A20,FIND("|",$A20)-1)),3)),IFERROR(VALUE(LEFT(LOWER(LEFT($A20,FIND("|",$A20)-1)),2)),IFERROR(VALUE(LEFT(LOWER(LEFT($A20,FIND("|",$A20)-1)),1)),-1))),"000000")&MID(LOWER(LEFT($A20,FIND("|",$A20)-1)),LEN(TEXT(IFERROR(VALUE(LEFT(LOWER(LEFT($A20,FIND("|",$A20)-1)),3)),IFERROR(VALUE(LEFT(LOWER(LEFT($A20,FIND("|",$A20)-1)),2)),IFERROR(VALUE(LEFT(LOWER(LEFT($A20,FIND("|",$A20)-1)),1)),-1))),"0"))+1,99),LOWER(LEFT($A20,FIND("|",$A20)-1)))&CHAR(9)&TEXT(IF(SUBSTITUTE(MID($A20,FIND("|",$A20)+1,50),"'","")="",0,IFERROR(VALUE(SUBSTITUTE(MID($A20,FIND("|",$A20)+1,50),"'","")),999999)),"000000")&CHAR(9)&TEXT($B20,"0000")) | E20: =IF($D20="","",SUMPRODUCT(($D$5:$D$364<>"")*($D$5:$D$364<$D20))+1)
A21: {=IF(N(INDIRECT("'Pull Sheet'!C23"))>0,INDIRECT("'Pull Sheet'!A23")&"|"&INDIRECT("'Pull Sheet'!B23"),"")} | B21: =IF(AND($A21<>"",COUNTIF($A$5:$A21,$A21)=1),MAX($B$4:$B20)+1,"") | C21: {=IF($A21="","",N(INDIRECT("'Pull Sheet'!C23")))} | D21: =IF($B21="","",IF(IFERROR(VALUE(LEFT(LOWER(LEFT($A21,FIND("|",$A21)-1)),3)),IFERROR(VALUE(LEFT(LOWER(LEFT($A21,FIND("|",$A21)-1)),2)),IFERROR(VALUE(LEFT(LOWER(LEFT($A21,FIND("|",$A21)-1)),1)),-1)))>=0,TEXT(IFERROR(VALUE(LEFT(LOWER(LEFT($A21,FIND("|",$A21)-1)),3)),IFERROR(VALUE(LEFT(LOWER(LEFT($A21,FIND("|",$A21)-1)),2)),IFERROR(VALUE(LEFT(LOWER(LEFT($A21,FIND("|",$A21)-1)),1)),-1))),"000000")&MID(LOWER(LEFT($A21,FIND("|",$A21)-1)),LEN(TEXT(IFERROR(VALUE(LEFT(LOWER(LEFT($A21,FIND("|",$A21)-1)),3)),IFERROR(VALUE(LEFT(LOWER(LEFT($A21,FIND("|",$A21)-1)),2)),IFERROR(VALUE(LEFT(LOWER(LEFT($A21,FIND("|",$A21)-1)),1)),-1))),"0"))+1,99),LOWER(LEFT($A21,FIND("|",$A21)-1)))&CHAR(9)&TEXT(IF(SUBSTITUTE(MID($A21,FIND("|",$A21)+1,50),"'","")="",0,IFERROR(VALUE(SUBSTITUTE(MID($A21,FIND("|",$A21)+1,50),"'","")),999999)),"000000")&CHAR(9)&TEXT($B21,"0000")) | E21: =IF($D21="","",SUMPRODUCT(($D$5:$D$364<>"")*($D$5:$D$364<$D21))+1)
A22: {=IF(N(INDIRECT("'Pull Sheet'!C24"))>0,INDIRECT("'Pull Sheet'!A24")&"|"&INDIRECT("'Pull Sheet'!B24"),"")} | B22: =IF(AND($A22<>"",COUNTIF($A$5:$A22,$A22)=1),MAX($B$4:$B21)+1,"") | C22: {=IF($A22="","",N(INDIRECT("'Pull Sheet'!C24")))} | D22: =IF($B22="","",IF(IFERROR(VALUE(LEFT(LOWER(LEFT($A22,FIND("|",$A22)-1)),3)),IFERROR(VALUE(LEFT(LOWER(LEFT($A22,FIND("|",$A22)-1)),2)),IFERROR(VALUE(LEFT(LOWER(LEFT($A22,FIND("|",$A22)-1)),1)),-1)))>=0,TEXT(IFERROR(VALUE(LEFT(LOWER(LEFT($A22,FIND("|",$A22)-1)),3)),IFERROR(VALUE(LEFT(LOWER(LEFT($A22,FIND("|",$A22)-1)),2)),IFERROR(VALUE(LEFT(LOWER(LEFT($A22,FIND("|",$A22)-1)),1)),-1))),"000000")&MID(LOWER(LEFT($A22,FIND("|",$A22)-1)),LEN(TEXT(IFERROR(VALUE(LEFT(LOWER(LEFT($A22,FIND("|",$A22)-1)),3)),IFERROR(VALUE(LEFT(LOWER(LEFT($A22,FIND("|",$A22)-1)),2)),IFERROR(VALUE(LEFT(LOWER(LEFT($A22,FIND("|",$A22)-1)),1)),-1))),"0"))+1,99),LOWER(LEFT($A22,FIND("|",$A22)-1)))&CHAR(9)&TEXT(IF(SUBSTITUTE(MID($A22,FIND("|",$A22)+1,50),"'","")="",0,IFERROR(VALUE(SUBSTITUTE(MID($A22,FIND("|",$A22)+1,50),"'","")),999999)),"000000")&CHAR(9)&TEXT($B22,"0000")) | E22: =IF($D22="","",SUMPRODUCT(($D$5:$D$364<>"")*($D$5:$D$364<$D22))+1)
A23: {=IF(N(INDIRECT("'Pull Sheet'!C25"))>0,INDIRECT("'Pull Sheet'!A25")&"|"&INDIRECT("'Pull Sheet'!B25"),"")} | B23: =IF(AND($A23<>"",COUNTIF($A$5:$A23,$A23)=1),MAX($B$4:$B22)+1,"") | C23: {=IF($A23="","",N(INDIRECT("'Pull Sheet'!C25")))} | D23: =IF($B23="","",IF(IFERROR(VALUE(LEFT(LOWER(LEFT($A23,FIND("|",$A23)-1)),3)),IFERROR(VALUE(LEFT(LOWER(LEFT($A23,FIND("|",$A23)-1)),2)),IFERROR(VALUE(LEFT(LOWER(LEFT($A23,FIND("|",$A23)-1)),1)),-1)))>=0,TEXT(IFERROR(VALUE(LEFT(LOWER(LEFT($A23,FIND("|",$A23)-1)),3)),IFERROR(VALUE(LEFT(LOWER(LEFT($A23,FIND("|",$A23)-1)),2)),IFERROR(VALUE(LEFT(LOWER(LEFT($A23,FIND("|",$A23)-1)),1)),-1))),"000000")&MID(LOWER(LEFT($A23,FIND("|",$A23)-1)),LEN(TEXT(IFERROR(VALUE(LEFT(LOWER(LEFT($A23,FIND("|",$A23)-1)),3)),IFERROR(VALUE(LEFT(LOWER(LEFT($A23,FIND("|",$A23)-1)),2)),IFERROR(VALUE(LEFT(LOWER(LEFT($A23,FIND("|",$A23)-1)),1)),-1))),"0"))+1,99),LOWER(LEFT($A23,FIND("|",$A23)-1)))&CHAR(9)&TEXT(IF(SUBSTITUTE(MID($A23,FIND("|",$A23)+1,50),"'","")="",0,IFERROR(VALUE(SUBSTITUTE(MID($A23,FIND("|",$A23)+1,50),"'","")),999999)),"000000")&CHAR(9)&TEXT($B23,"0000")) | E23: =IF($D23="","",SUMPRODUCT(($D$5:$D$364<>"")*($D$5:$D$364<$D23))+1)
A24: {=IF(N(INDIRECT("'Pull Sheet'!C26"))>0,INDIRECT("'Pull Sheet'!A26")&"|"&INDIRECT("'Pull Sheet'!B26"),"")} | B24: =IF(AND($A24<>"",COUNTIF($A$5:$A24,$A24)=1),MAX($B$4:$B23)+1,"") | C24: {=IF($A24="","",N(INDIRECT("'Pull Sheet'!C26")))} | D24: =IF($B24="","",IF(IFERROR(VALUE(LEFT(LOWER(LEFT($A24,FIND("|",$A24)-1)),3)),IFERROR(VALUE(LEFT(LOWER(LEFT($A24,FIND("|",$A24)-1)),2)),IFERROR(VALUE(LEFT(LOWER(LEFT($A24,FIND("|",$A24)-1)),1)),-1)))>=0,TEXT(IFERROR(VALUE(LEFT(LOWER(LEFT($A24,FIND("|",$A24)-1)),3)),IFERROR(VALUE(LEFT(LOWER(LEFT($A24,FIND("|",$A24)-1)),2)),IFERROR(VALUE(LEFT(LOWER(LEFT($A24,FIND("|",$A24)-1)),1)),-1))),"000000")&MID(LOWER(LEFT($A24,FIND("|",$A24)-1)),LEN(TEXT(IFERROR(VALUE(LEFT(LOWER(LEFT($A24,FIND("|",$A24)-1)),3)),IFERROR(VALUE(LEFT(LOWER(LEFT($A24,FIND("|",$A24)-1)),2)),IFERROR(VALUE(LEFT(LOWER(LEFT($A24,FIND("|",$A24)-1)),1)),-1))),"0"))+1,99),LOWER(LEFT($A24,FIND("|",$A24)-1)))&CHAR(9)&TEXT(IF(SUBSTITUTE(MID($A24,FIND("|",$A24)+1,50),"'","")="",0,IFERROR(VALUE(SUBSTITUTE(MID($A24,FIND("|",$A24)+1,50),"'","")),999999)),"000000")&CHAR(9)&TEXT($B24,"0000")) | E24: =IF($D24="","",SUMPRODUCT(($D$5:$D$364<>"")*($D$5:$D$364<$D24))+1)
A25: {=IF(N(INDIRECT("'Pull Sheet'!C27"))>0,INDIRECT("'Pull Sheet'!A27")&"|"&INDIRECT("'Pull Sheet'!B27"),"")} | B25: =IF(AND($A25<>"",COUNTIF($A$5:$A25,$A25)=1),MAX($B$4:$B24)+1,"") | C25: {=IF($A25="","",N(INDIRECT("'Pull Sheet'!C27")))} | D25: =IF($B25="","",IF(IFERROR(VALUE(LEFT(LOWER(LEFT($A25,FIND("|",$A25)-1)),3)),IFERROR(VALUE(LEFT(LOWER(LEFT($A25,FIND("|",$A25)-1)),2)),IFERROR(VALUE(LEFT(LOWER(LEFT($A25,FIND("|",$A25)-1)),1)),-1)))>=0,TEXT(IFERROR(VALUE(LEFT(LOWER(LEFT($A25,FIND("|",$A25)-1)),3)),IFERROR(VALUE(LEFT(LOWER(LEFT($A25,FIND("|",$A25)-1)),2)),IFERROR(VALUE(LEFT(LOWER(LEFT($A25,FIND("|",$A25)-1)),1)),-1))),"000000")&MID(LOWER(LEFT($A25,FIND("|",$A25)-1)),LEN(TEXT(IFERROR(VALUE(LEFT(LOWER(LEFT($A25,FIND("|",$A25)-1)),3)),IFERROR(VALUE(LEFT(LOWER(LEFT($A25,FIND("|",$A25)-1)),2)),IFERROR(VALUE(LEFT(LOWER(LEFT($A25,FIND("|",$A25)-1)),1)),-1))),"0"))+1,99),LOWER(LEFT($A25,FIND("|",$A25)-1)))&CHAR(9)&TEXT(IF(SUBSTITUTE(MID($A25,FIND("|",$A25)+1,50),"'","")="",0,IFERROR(VALUE(SUBSTITUTE(MID($A25,FIND("|",$A25)+1,50),"'","")),999999)),"000000")&CHAR(9)&TEXT($B25,"0000")) | E25: =IF($D25="","",SUMPRODUCT(($D$5:$D$364<>"")*($D$5:$D$364<$D25))+1)
A26: {=IF(N(INDIRECT("'Pull Sheet'!C28"))>0,INDIRECT("'Pull Sheet'!A28")&"|"&INDIRECT("'Pull Sheet'!B28"),"")} | B26: =IF(AND($A26<>"",COUNTIF($A$5:$A26,$A26)=1),MAX($B$4:$B25)+1,"") | C26: {=IF($A26="","",N(INDIRECT("'Pull Sheet'!C28")))} | D26: =IF($B26="","",IF(IFERROR(VALUE(LEFT(LOWER(LEFT($A26,FIND("|",$A26)-1)),3)),IFERROR(VALUE(LEFT(LOWER(LEFT($A26,FIND("|",$A26)-1)),2)),IFERROR(VALUE(LEFT(LOWER(LEFT($A26,FIND("|",$A26)-1)),1)),-1)))>=0,TEXT(IFERROR(VALUE(LEFT(LOWER(LEFT($A26,FIND("|",$A26)-1)),3)),IFERROR(VALUE(LEFT(LOWER(LEFT($A26,FIND("|",$A26)-1)),2)),IFERROR(VALUE(LEFT(LOWER(LEFT($A26,FIND("|",$A26)-1)),1)),-1))),"000000")&MID(LOWER(LEFT($A26,FIND("|",$A26)-1)),LEN(TEXT(IFERROR(VALUE(LEFT(LOWER(LEFT($A26,FIND("|",$A26)-1)),3)),IFERROR(VALUE(LEFT(LOWER(LEFT($A26,FIND("|",$A26)-1)),2)),IFERROR(VALUE(LEFT(LOWER(LEFT($A26,FIND("|",$A26)-1)),1)),-1))),"0"))+1,99),LOWER(LEFT($A26,FIND("|",$A26)-1)))&CHAR(9)&TEXT(IF(SUBSTITUTE(MID($A26,FIND("|",$A26)+1,50),"'","")="",0,IFERROR(VALUE(SUBSTITUTE(MID($A26,FIND("|",$A26)+1,50),"'","")),999999)),"000000")&CHAR(9)&TEXT($B26,"0000")) | E26: =IF($D26="","",SUMPRODUCT(($D$5:$D$364<>"")*($D$5:$D$364<$D26))+1)
A27: {=IF(N(INDIRECT("'Pull Sheet'!C29"))>0,INDIRECT("'Pull Sheet'!A29")&"|"&INDIRECT("'Pull Sheet'!B29"),"")} | B27: =IF(AND($A27<>"",COUNTIF($A$5:$A27,$A27)=1),MAX($B$4:$B26)+1,"") | C27: {=IF($A27="","",N(INDIRECT("'Pull Sheet'!C29")))} | D27: =IF($B27="","",IF(IFERROR(VALUE(LEFT(LOWER(LEFT($A27,FIND("|",$A27)-1)),3)),IFERROR(VALUE(LEFT(LOWER(LEFT($A27,FIND("|",$A27)-1)),2)),IFERROR(VALUE(LEFT(LOWER(LEFT($A27,FIND("|",$A27)-1)),1)),-1)))>=0,TEXT(IFERROR(VALUE(LEFT(LOWER(LEFT($A27,FIND("|",$A27)-1)),3)),IFERROR(VALUE(LEFT(LOWER(LEFT($A27,FIND("|",$A27)-1)),2)),IFERROR(VALUE(LEFT(LOWER(LEFT($A27,FIND("|",$A27)-1)),1)),-1))),"000000")&MID(LOWER(LEFT($A27,FIND("|",$A27)-1)),LEN(TEXT(IFERROR(VALUE(LEFT(LOWER(LEFT($A27,FIND("|",$A27)-1)),3)),IFERROR(VALUE(LEFT(LOWER(LEFT($A27,FIND("|",$A27)-1)),2)),IFERROR(VALUE(LEFT(LOWER(LEFT($A27,FIND("|",$A27)-1)),1)),-1))),"0"))+1,99),LOWER(LEFT($A27,FIND("|",$A27)-1)))&CHAR(9)&TEXT(IF(SUBSTITUTE(MID($A27,FIND("|",$A27)+1,50),"'","")="",0,IFERROR(VALUE(SUBSTITUTE(MID($A27,FIND("|",$A27)+1,50),"'","")),999999)),"000000")&CHAR(9)&TEXT($B27,"0000")) | E27: =IF($D27="","",SUMPRODUCT(($D$5:$D$364<>"")*($D$5:$D$364<$D27))+1)
A28: {=IF(N(INDIRECT("'Pull Sheet'!C30"))>0,INDIRECT("'Pull Sheet'!A30")&"|"&INDIRECT("'Pull Sheet'!B30"),"")} | B28: =IF(AND($A28<>"",COUNTIF($A$5:$A28,$A28)=1),MAX($B$4:$B27)+1,"") | C28: {=IF($A28="","",N(INDIRECT("'Pull Sheet'!C30")))} | D28: =IF($B28="","",IF(IFERROR(VALUE(LEFT(LOWER(LEFT($A28,FIND("|",$A28)-1)),3)),IFERROR(VALUE(LEFT(LOWER(LEFT($A28,FIND("|",$A28)-1)),2)),IFERROR(VALUE(LEFT(LOWER(LEFT($A28,FIND("|",$A28)-1)),1)),-1)))>=0,TEXT(IFERROR(VALUE(LEFT(LOWER(LEFT($A28,FIND("|",$A28)-1)),3)),IFERROR(VALUE(LEFT(LOWER(LEFT($A28,FIND("|",$A28)-1)),2)),IFERROR(VALUE(LEFT(LOWER(LEFT($A28,FIND("|",$A28)-1)),1)),-1))),"000000")&MID(LOWER(LEFT($A28,FIND("|",$A28)-1)),LEN(TEXT(IFERROR(VALUE(LEFT(LOWER(LEFT($A28,FIND("|",$A28)-1)),3)),IFERROR(VALUE(LEFT(LOWER(LEFT($A28,FIND("|",$A28)-1)),2)),IFERROR(VALUE(LEFT(LOWER(LEFT($A28,FIND("|",$A28)-1)),1)),-1))),"0"))+1,99),LOWER(LEFT($A28,FIND("|",$A28)-1)))&CHAR(9)&TEXT(IF(SUBSTITUTE(MID($A28,FIND("|",$A28)+1,50),"'","")="",0,IFERROR(VALUE(SUBSTITUTE(MID($A28,FIND("|",$A28)+1,50),"'","")),999999)),"000000")&CHAR(9)&TEXT($B28,"0000")) | E28: =IF($D28="","",SUMPRODUCT(($D$5:$D$364<>"")*($D$5:$D$364<$D28))+1)
A29: {=IF(N(INDIRECT("'Pull Sheet'!C31"))>0,INDIRECT("'Pull Sheet'!A31")&"|"&INDIRECT("'Pull Sheet'!B31"),"")} | B29: =IF(AND($A29<>"",COUNTIF($A$5:$A29,$A29)=1),MAX($B$4:$B28)+1,"") | C29: {=IF($A29="","",N(INDIRECT("'Pull Sheet'!C31")))} | D29: =IF($B29="","",IF(IFERROR(VALUE(LEFT(LOWER(LEFT($A29,FIND("|",$A29)-1)),3)),IFERROR(VALUE(LEFT(LOWER(LEFT($A29,FIND("|",$A29)-1)),2)),IFERROR(VALUE(LEFT(LOWER(LEFT($A29,FIND("|",$A29)-1)),1)),-1)))>=0,TEXT(IFERROR(VALUE(LEFT(LOWER(LEFT($A29,FIND("|",$A29)-1)),3)),IFERROR(VALUE(LEFT(LOWER(LEFT($A29,FIND("|",$A29)-1)),2)),IFERROR(VALUE(LEFT(LOWER(LEFT($A29,FIND("|",$A29)-1)),1)),-1))),"000000")&MID(LOWER(LEFT($A29,FIND("|",$A29)-1)),LEN(TEXT(IFERROR(VALUE(LEFT(LOWER(LEFT($A29,FIND("|",$A29)-1)),3)),IFERROR(VALUE(LEFT(LOWER(LEFT($A29,FIND("|",$A29)-1)),2)),IFERROR(VALUE(LEFT(LOWER(LEFT($A29,FIND("|",$A29)-1)),1)),-1))),"0"))+1,99),LOWER(LEFT($A29,FIND("|",$A29)-1)))&CHAR(9)&TEXT(IF(SUBSTITUTE(MID($A29,FIND("|",$A29)+1,50),"'","")="",0,IFERROR(VALUE(SUBSTITUTE(MID($A29,FIND("|",$A29)+1,50),"'","")),999999)),"000000")&CHAR(9)&TEXT($B29,"0000")) | E29: =IF($D29="","",SUMPRODUCT(($D$5:$D$364<>"")*($D$5:$D$364<$D29))+1)
A30: {=IF(N(INDIRECT("'Pull Sheet'!C32"))>0,INDIRECT("'Pull Sheet'!A32")&"|"&INDIRECT("'Pull Sheet'!B32"),"")} | B30: =IF(AND($A30<>"",COUNTIF($A$5:$A30,$A30)=1),MAX($B$4:$B29)+1,"") | C30: {=IF($A30="","",N(INDIRECT("'Pull Sheet'!C32")))} | D30: =IF($B30="","",IF(IFERROR(VALUE(LEFT(LOWER(LEFT($A30,FIND("|",$A30)-1)),3)),IFERROR(VALUE(LEFT(LOWER(LEFT($A30,FIND("|",$A30)-1)),2)),IFERROR(VALUE(LEFT(LOWER(LEFT($A30,FIND("|",$A30)-1)),1)),-1)))>=0,TEXT(IFERROR(VALUE(LEFT(LOWER(LEFT($A30,FIND("|",$A30)-1)),3)),IFERROR(VALUE(LEFT(LOWER(LEFT($A30,FIND("|",$A30)-1)),2)),IFERROR(VALUE(LEFT(LOWER(LEFT($A30,FIND("|",$A30)-1)),1)),-1))),"000000")&MID(LOWER(LEFT($A30,FIND("|",$A30)-1)),LEN(TEXT(IFERROR(VALUE(LEFT(LOWER(LEFT($A30,FIND("|",$A30)-1)),3)),IFERROR(VALUE(LEFT(LOWER(LEFT($A30,FIND("|",$A30)-1)),2)),IFERROR(VALUE(LEFT(LOWER(LEFT($A30,FIND("|",$A30)-1)),1)),-1))),"0"))+1,99),LOWER(LEFT($A30,FIND("|",$A30)-1)))&CHAR(9)&TEXT(IF(SUBSTITUTE(MID($A30,FIND("|",$A30)+1,50),"'","")="",0,IFERROR(VALUE(SUBSTITUTE(MID($A30,FIND("|",$A30)+1,50),"'","")),999999)),"000000")&CHAR(9)&TEXT($B30,"0000")) | E30: =IF($D30="","",SUMPRODUCT(($D$5:$D$364<>"")*($D$5:$D$364<$D30))+1)
A31: {=IF(N(INDIRECT("'Pull Sheet'!C33"))>0,INDIRECT("'Pull Sheet'!A33")&"|"&INDIRECT("'Pull Sheet'!B33"),"")} | B31: =IF(AND($A31<>"",COUNTIF($A$5:$A31,$A31)=1),MAX($B$4:$B30)+1,"") | C31: {=IF($A31="","",N(INDIRECT("'Pull Sheet'!C33")))} | D31: =IF($B31="","",IF(IFERROR(VALUE(LEFT(LOWER(LEFT($A31,FIND("|",$A31)-1)),3)),IFERROR(VALUE(LEFT(LOWER(LEFT($A31,FIND("|",$A31)-1)),2)),IFERROR(VALUE(LEFT(LOWER(LEFT($A31,FIND("|",$A31)-1)),1)),-1)))>=0,TEXT(IFERROR(VALUE(LEFT(LOWER(LEFT($A31,FIND("|",$A31)-1)),3)),IFERROR(VALUE(LEFT(LOWER(LEFT($A31,FIND("|",$A31)-1)),2)),IFERROR(VALUE(LEFT(LOWER(LEFT($A31,FIND("|",$A31)-1)),1)),-1))),"000000")&MID(LOWER(LEFT($A31,FIND("|",$A31)-1)),LEN(TEXT(IFERROR(VALUE(LEFT(LOWER(LEFT($A31,FIND("|",$A31)-1)),3)),IFERROR(VALUE(LEFT(LOWER(LEFT($A31,FIND("|",$A31)-1)),2)),IFERROR(VALUE(LEFT(LOWER(LEFT($A31,FIND("|",$A31)-1)),1)),-1))),"0"))+1,99),LOWER(LEFT($A31,FIND("|",$A31)-1)))&CHAR(9)&TEXT(IF(SUBSTITUTE(MID($A31,FIND("|",$A31)+1,50),"'","")="",0,IFERROR(VALUE(SUBSTITUTE(MID($A31,FIND("|",$A31)+1,50),"'","")),999999)),"000000")&CHAR(9)&TEXT($B31,"0000")) | E31: =IF($D31="","",SUMPRODUCT(($D$5:$D$364<>"")*($D$5:$D$364<$D31))+1)
A32: {=IF(N(INDIRECT("'Pull Sheet'!C34"))>0,INDIRECT("'Pull Sheet'!A34")&"|"&INDIRECT("'Pull Sheet'!B34"),"")} | B32: =IF(AND($A32<>"",COUNTIF($A$5:$A32,$A32)=1),MAX($B$4:$B31)+1,"") | C32: {=IF($A32="","",N(INDIRECT("'Pull Sheet'!C34")))} | D32: =IF($B32="","",IF(IFERROR(VALUE(LEFT(LOWER(LEFT($A32,FIND("|",$A32)-1)),3)),IFERROR(VALUE(LEFT(LOWER(LEFT($A32,FIND("|",$A32)-1)),2)),IFERROR(VALUE(LEFT(LOWER(LEFT($A32,FIND("|",$A32)-1)),1)),-1)))>=0,TEXT(IFERROR(VALUE(LEFT(LOWER(LEFT($A32,FIND("|",$A32)-1)),3)),IFERROR(VALUE(LEFT(LOWER(LEFT($A32,FIND("|",$A32)-1)),2)),IFERROR(VALUE(LEFT(LOWER(LEFT($A32,FIND("|",$A32)-1)),1)),-1))),"000000")&MID(LOWER(LEFT($A32,FIND("|",$A32)-1)),LEN(TEXT(IFERROR(VALUE(LEFT(LOWER(LEFT($A32,FIND("|",$A32)-1)),3)),IFERROR(VALUE(LEFT(LOWER(LEFT($A32,FIND("|",$A32)-1)),2)),IFERROR(VALUE(LEFT(LOWER(LEFT($A32,FIND("|",$A32)-1)),1)),-1))),"0"))+1,99),LOWER(LEFT($A32,FIND("|",$A32)-1)))&CHAR(9)&TEXT(IF(SUBSTITUTE(MID($A32,FIND("|",$A32)+1,50),"'","")="",0,IFERROR(VALUE(SUBSTITUTE(MID($A32,FIND("|",$A32)+1,50),"'","")),999999)),"000000")&CHAR(9)&TEXT($B32,"0000")) | E32: =IF($D32="","",SUMPRODUCT(($D$5:$D$364<>"")*($D$5:$D$364<$D32))+1)
A33: {=IF(N(INDIRECT("'Pull Sheet'!C35"))>0,INDIRECT("'Pull Sheet'!A35")&"|"&INDIRECT("'Pull Sheet'!B35"),"")} | B33: =IF(AND($A33<>"",COUNTIF($A$5:$A33,$A33)=1),MAX($B$4:$B32)+1,"") | C33: {=IF($A33="","",N(INDIRECT("'Pull Sheet'!C35")))} | D33: =IF($B33="","",IF(IFERROR(VALUE(LEFT(LOWER(LEFT($A33,FIND("|",$A33)-1)),3)),IFERROR(VALUE(LEFT(LOWER(LEFT($A33,FIND("|",$A33)-1)),2)),IFERROR(VALUE(LEFT(LOWER(LEFT($A33,FIND("|",$A33)-1)),1)),-1)))>=0,TEXT(IFERROR(VALUE(LEFT(LOWER(LEFT($A33,FIND("|",$A33)-1)),3)),IFERROR(VALUE(LEFT(LOWER(LEFT($A33,FIND("|",$A33)-1)),2)),IFERROR(VALUE(LEFT(LOWER(LEFT($A33,FIND("|",$A33)-1)),1)),-1))),"000000")&MID(LOWER(LEFT($A33,FIND("|",$A33)-1)),LEN(TEXT(IFERROR(VALUE(LEFT(LOWER(LEFT($A33,FIND("|",$A33)-1)),3)),IFERROR(VALUE(LEFT(LOWER(LEFT($A33,FIND("|",$A33)-1)),2)),IFERROR(VALUE(LEFT(LOWER(LEFT($A33,FIND("|",$A33)-1)),1)),-1))),"0"))+1,99),LOWER(LEFT($A33,FIND("|",$A33)-1)))&CHAR(9)&TEXT(IF(SUBSTITUTE(MID($A33,FIND("|",$A33)+1,50),"'","")="",0,IFERROR(VALUE(SUBSTITUTE(MID($A33,FIND("|",$A33)+1,50),"'","")),999999)),"000000")&CHAR(9)&TEXT($B33,"0000")) | E33: =IF($D33="","",SUMPRODUCT(($D$5:$D$364<>"")*($D$5:$D$364<$D33))+1)
A34: {=IF(N(INDIRECT("'Pull Sheet'!C36"))>0,INDIRECT("'Pull Sheet'!A36")&"|"&INDIRECT("'Pull Sheet'!B36"),"")} | B34: =IF(AND($A34<>"",COUNTIF($A$5:$A34,$A34)=1),MAX($B$4:$B33)+1,"") | C34: {=IF($A34="","",N(INDIRECT("'Pull Sheet'!C36")))} | D34: =IF($B34="","",IF(IFERROR(VALUE(LEFT(LOWER(LEFT($A34,FIND("|",$A34)-1)),3)),IFERROR(VALUE(LEFT(LOWER(LEFT($A34,FIND("|",$A34)-1)),2)),IFERROR(VALUE(LEFT(LOWER(LEFT($A34,FIND("|",$A34)-1)),1)),-1)))>=0,TEXT(IFERROR(VALUE(LEFT(LOWER(LEFT($A34,FIND("|",$A34)-1)),3)),IFERROR(VALUE(LEFT(LOWER(LEFT($A34,FIND("|",$A34)-1)),2)),IFERROR(VALUE(LEFT(LOWER(LEFT($A34,FIND("|",$A34)-1)),1)),-1))),"000000")&MID(LOWER(LEFT($A34,FIND("|",$A34)-1)),LEN(TEXT(IFERROR(VALUE(LEFT(LOWER(LEFT($A34,FIND("|",$A34)-1)),3)),IFERROR(VALUE(LEFT(LOWER(LEFT($A34,FIND("|",$A34)-1)),2)),IFERROR(VALUE(LEFT(LOWER(LEFT($A34,FIND("|",$A34)-1)),1)),-1))),"0"))+1,99),LOWER(LEFT($A34,FIND("|",$A34)-1)))&CHAR(9)&TEXT(IF(SUBSTITUTE(MID($A34,FIND("|",$A34)+1,50),"'","")="",0,IFERROR(VALUE(SUBSTITUTE(MID($A34,FIND("|",$A34)+1,50),"'","")),999999)),"000000")&CHAR(9)&TEXT($B34,"0000")) | E34: =IF($D34="","",SUMPRODUCT(($D$5:$D$364<>"")*($D$5:$D$364<$D34))+1)
A35: {=IF(N(INDIRECT("'Pull Sheet'!C37"))>0,INDIRECT("'Pull Sheet'!A37")&"|"&INDIRECT("'Pull Sheet'!B37"),"")} | B35: =IF(AND($A35<>"",COUNTIF($A$5:$A35,$A35)=1),MAX($B$4:$B34)+1,"") | C35: {=IF($A35="","",N(INDIRECT("'Pull Sheet'!C37")))} | D35: =IF($B35="","",IF(IFERROR(VALUE(LEFT(LOWER(LEFT($A35,FIND("|",$A35)-1)),3)),IFERROR(VALUE(LEFT(LOWER(LEFT($A35,FIND("|",$A35)-1)),2)),IFERROR(VALUE(LEFT(LOWER(LEFT($A35,FIND("|",$A35)-1)),1)),-1)))>=0,TEXT(IFERROR(VALUE(LEFT(LOWER(LEFT($A35,FIND("|",$A35)-1)),3)),IFERROR(VALUE(LEFT(LOWER(LEFT($A35,FIND("|",$A35)-1)),2)),IFERROR(VALUE(LEFT(LOWER(LEFT($A35,FIND("|",$A35)-1)),1)),-1))),"000000")&MID(LOWER(LEFT($A35,FIND("|",$A35)-1)),LEN(TEXT(IFERROR(VALUE(LEFT(LOWER(LEFT($A35,FIND("|",$A35)-1)),3)),IFERROR(VALUE(LEFT(LOWER(LEFT($A35,FIND("|",$A35)-1)),2)),IFERROR(VALUE(LEFT(LOWER(LEFT($A35,FIND("|",$A35)-1)),1)),-1))),"0"))+1,99),LOWER(LEFT($A35,FIND("|",$A35)-1)))&CHAR(9)&TEXT(IF(SUBSTITUTE(MID($A35,FIND("|",$A35)+1,50),"'","")="",0,IFERROR(VALUE(SUBSTITUTE(MID($A35,FIND("|",$A35)+1,50),"'","")),999999)),"000000")&CHAR(9)&TEXT($B35,"0000")) | E35: =IF($D35="","",SUMPRODUCT(($D$5:$D$364<>"")*($D$5:$D$364<$D35))+1)
